Workbook

Sheet XQ5
A1: 开发区 | F1: 产品信息区 | O1: 46056 | S1: 46046 | T1: 45921 | AF1: 入full区 | BT1: 补货区 | CZ1: 46077 | DA1: 46072 | DB1: 46077 | DG1: 广告促销区 | DU1: 调价区 | EE1: 本月汇率（比索）： | EI1: 2.61 | EJ1: 毛利区 | EL1: 运费区 | ER1: 产品参数区 | FB1: 采购价更新区 | FF1: 参数更新区
A2: 开发日期 | B2: 选品标题（带链接） | C2: 蓝鲸7天销量 | D2: 蓝鲸30天销量 | E2: 抓取时间 | F2: 一类 | G2: 产品类型 | H2: 产品名 | J2: 产品标题（上架） | K2: SKU | L2: 上架编码 | M2: 状态 | N2: 购物体验分 | O2: 平台在线库存 | P2: 私仓 | Q2: 在墨库存销售天数 | R2: 评估 | S2: full分_旧产品数量 | T2: 仓储费产品__2月以上 | U2: 发货周期 | V2: 销售周期 | W2: 日均销量（7天） | X2: 在墨库存数 | AF2: full和 | AG2: 2.24-2.26 #62128153 | AH2: 2/16-2.18 #61590631 | AI2: 1/31-2/2 #60400687 | AJ2: 1/27-1/29 #60073000 | AK2: 1/27-1/29 #60072244 | AL2: 1/24-1/26 #60071284 | BS2: 私仓 | BT2: 在途总和 | CW2: 已采购 | CX2: 实际补货 | CY2: 理论补货 | CZ2: 7天销量(每日2点更新) | DA2: 7天销量(每日2点更新) | DB2: 单日销量 | DC2: 自然销量 | DD2: 广告销量 | DE2: 直接 | DF2: 间接 | DG2: 广告花费 | DH2: 展现量 | DI2: 点击数 | DJ2: Acos | DK2: TAcos7天 | DL2: TAcos30天 | DM2: ROAS输出值 | DN2: ROAS目标值 | DO2: 广告开关 | DP2: 广告组 | DQ2: 促销截止时间 | DU2: 评估 | DX2: 46078 | DY2: 46077 | DZ2: 2月21 | EA2: 46069 | EB2: 46067 | EC2: 46064 | ED2: 46057 | EE2: 售价M·XN | EF2: 原价 | EG2: 采购价RMB | EH2: 投入产出比 | EI2: 采购价MXN | EJ2: 海运毛利 | EK2: 海运毛利率 | EL2: 海运头程 | EM2: 是否包邮 | EN2: 仓库操作费 | EO2: ML佣金（经典曝光/优质曝光） | EP2: 包邮-尾端配送费 | EQ2: 企业增值税10.5% | ER2: 实重kg | ES2: 长cm | ET2: 宽cm | EU2: 高cm | EV2: 体积重 | EW2: 计费重 | EX2: CBM | EZ2: 日均实时销量7天 | FB2: 新价格 | FC2: 旧价格 | FF2: 包装重量kg | FG2: 包装长cm | FH2: 包装宽cm | FI2: 包装高cm | FK2: 散货1/装柜2
B3: Yyugolo Mesa Cromada Uso Rudo Sencilla Con Ruedas Inoxidable | Envío gratis (mercadolibre.com.mx) | C3: 46 | D3: 138 | E3: 45887 | G3: 推车 | H3: 二层小推车-外拦 | J3: Yyugolo Mesa Cromada Uso Rudo Sencilla Con Ruedas Inoxidable | K3: XQ5-ECXTC-WL | L3: 4238699688 | M3: 已上架 | N3: =_xlfn.XLOOKUP(L3,数据更新表!J:J,数据更新表!K:K) -> 100 | O3: =IFERROR(_xlfn.XLOOKUP(K3,数据更新表!A:A,数据更新表!B:B),"0") -> 16 | P3: =_xlfn.XLOOKUP(K3,[1]库销表!$F:$F,[1]库销表!$L:$L) -> 0 | Q3: =X3/W3 -> 19.6 | S3: =_xlfn.XLOOKUP(K3,数据更新表!R:R,数据更新表!S:S) -> #N/A | T3: =_xlfn.XLOOKUP(K3,数据更新表!V:V,数据更新表!W:W) -> #N/A | V3: =IFERROR(7*O3/CZ3,"0") -> 5.6 | W3: =CZ3/7 -> 2.8571429 | X3: =O3+P3+SUM(AH3:BQ3) -> 56 | AF3: =SUM(AG3:BQ3) -> 100 | AG3: 60 | AH3: 40 | BS3: =_xlfn.XLOOKUP(K3,[1]库销表!$F:$F,[1]库销表!$L:$L) -> 0 | BT3: =SUM(BU3:CV3) -> 0 | CW3: =_xlfn.XLOOKUP(K3,[1]库销表!$F:$F,[1]库销表!$IE:$IE) -> 0 | CX3: =_xlfn.XLOOKUP(K3,[1]库销表!$F:$F,[1]库销表!$IF:$IF) -> 0 | CY3: =_xlfn.XLOOKUP(K3,[1]库销表!$F:$F,[1]库销表!$FL:$FL) -> 0 | CZ3: =_xlfn.XLOOKUP(K3,数据更新表!E:E,数据更新表!F:F,0) -> 20 | DA3: 1 | DB3: =_xlfn.XLOOKUP(K3,数据更新表!E:E,数据更新表!G:G) -> 1 | DC3: =_xlfn.XLOOKUP(L3,数据更新表!Z:Z,数据更新表!AH:AH) -> 8 | DD3: =_xlfn.XLOOKUP(L3,数据更新表!Z:Z,数据更新表!AE:AE) -> 12 | DE3: =_xlfn.XLOOKUP(L3,数据更新表!Z:Z,数据更新表!AF:AF) -> 12 | DF3: =_xlfn.XLOOKUP(K3,数据更新表!Z:Z,数据更新表!AG:AG) -> #N/A | DG3: =_xlfn.XLOOKUP(L3,数据更新表!Z:Z,数据更新表!AD:AD) -> 642.72 | DH3: =_xlfn.XLOOKUP(L3,数据更新表!Z:Z,数据更新表!AA:AA) -> 9008 | DI3: =_xlfn.XLOOKUP(L3,数据更新表!Z:Z,数据更新表!AB:AB) -> 119 | DJ3: =_xlfn.XLOOKUP(L3,数据更新表!Z:Z,数据更新表!AC:AC) -> 3.20% | DK3: =_xlfn.XLOOKUP(L3,数据更新表!Z:Z,数据更新表!AI:AI) -> 1.93% | DL3: =_xlfn.XLOOKUP(L3,数据更新表!AL:AL,数据更新表!AM:AM) -> 1.97% | DM3: =_xlfn.XLOOKUP(L3,数据更新表!Z:Z,数据更新表!AJ:AJ) -> 31.25 | DN3: 20 | DO3: 关 | DP3: Medical trolley | DQ3: 46052 | DU3: 独家 | DZ3: 关广 | EE3: 1699 | EF3: =EE3/0.7 -> 2427.1429 | EG3: 120 | EH3: =EJ3/(EI3+EL3) -> 0.57467775 | EI3: =EG3*$EI$1 -> 313.2 | EJ3: =EE3-EI3-EL3-EO3-EN3-EP3-EQ3 -> 356.49355 | EK3: =EJ3/EE3 -> 0.20982552 | EL3: =EX3*2500*$EI$1 -> 307.13645 | EM3: =IF(EE3>299,"是","否") -> 是 | EN3: =EE3*0.05 -> 84.95 | EO3: =EE3*0.175 -> 297.325 | EP3: =IF(EE3<299,IF(EE3<99,25,IF(EE3<=149,30,IF(EE3<=299,37,85))),IF(EE3<=498,_xlfn.XLOOKUP(EW3,运费表!A:A,运费表!C:C,"重量超限",-1),_xlfn.XLOOKUP(EW3,运费表!A:A,运费表!D:D,"重量超限",-1))) -> 161.5 | EQ3: =EE3*0.105 -> 178.395 | ER3: =_xlfn.XLOOKUP(K3,[4]目录表!$H:$H,[4]目录表!$X:$X) -> 7 | ES3: =_xlfn.XLOOKUP(K3,[4]目录表!$H:$H,[4]目录表!$Y:$Y) -> 82 | ET3: =_xlfn.XLOOKUP(K3,[4]目录表!$H:$H,[4]目录表!$Z:$Z) -> 44 | EU3: =_xlfn.XLOOKUP(K3,[4]目录表!$H:$H,[4]目录表!$AA:$AA) -> 14 | EV3: =ES3*ET3*EU3/5000 -> 10.1024 | EW3: =IF(EV3>=ER3,EV3,ER3) -> 10.1024 | EX3: =_xlfn.XLOOKUP(K3,[2]目录表!$H:$H,[2]目录表!$AB:$AB) -> 0.04707072 | EZ3: =CZ3/7 -> 2.8571429 | FK3: =_xlfn.XLOOKUP(K3,[2]目录表!$H:$H,[2]目录表!$AJ:$AJ) -> 装柜
B4: Mesa Para Intrumental Medico Mesa Pasteur Mesa Con 4 Ruedas | Meses sin interés (mercadolibre.com.mx) | C4: 27 | D4: 42 | E4: 45887 | G4: 推车 | H4: 二层小推车-内拦 | J4: Mesa Para Intrumental Medico Mesa Pasteur Mesa Con 4 Ruedas | K4: XQ5-ECXTC-NL | L4: 4238574572 | M4: 已上架 | N4: =_xlfn.XLOOKUP(L4,数据更新表!J:J,数据更新表!K:K) -> 100 | O4: =IFERROR(_xlfn.XLOOKUP(K4,数据更新表!A:A,数据更新表!B:B),"0") -> 8 | P4: =_xlfn.XLOOKUP(K4,[1]库销表!$F:$F,[1]库销表!$L:$L) -> 0 | Q4: =X4/W4 -> 10.83871 | S4: =_xlfn.XLOOKUP(K4,数据更新表!R:R,数据更新表!S:S) -> #N/A | T4: =_xlfn.XLOOKUP(K4,数据更新表!V:V,数据更新表!W:W) -> #N/A | V4: =IFERROR(7*O4/CZ4,"0") -> 1.8064516 | W4: =CZ4/7 -> 4.4285714 | X4: =O4+P4+SUM(AH4:BQ4) -> 48 | AF4: =SUM(AG4:BQ4) -> 100 | AG4: 60 | AH4: 40 | BS4: =_xlfn.XLOOKUP(K4,[1]库销表!$F:$F,[1]库销表!$L:$L) -> 0 | BT4: =SUM(BU4:CV4) -> 0 | CW4: =_xlfn.XLOOKUP(K4,[1]库销表!$F:$F,[1]库销表!$IE:$IE) -> 0 | CX4: =_xlfn.XLOOKUP(K4,[1]库销表!$F:$F,[1]库销表!$IF:$IF) -> 0 | CY4: =_xlfn.XLOOKUP(K4,[1]库销表!$F:$F,[1]库销表!$FL:$FL) -> 0 | CZ4: =_xlfn.XLOOKUP(K4,数据更新表!E:E,数据更新表!F:F,0) -> 31 | DA4: 1 | DB4: =_xlfn.XLOOKUP(K4,数据更新表!E:E,数据更新表!G:G) -> 3 | DC4: =_xlfn.XLOOKUP(L4,数据更新表!Z:Z,数据更新表!AH:AH) -> 10 | DD4: =_xlfn.XLOOKUP(L4,数据更新表!Z:Z,数据更新表!AE:AE) -> 21 | DE4: =_xlfn.XLOOKUP(L4,数据更新表!Z:Z,数据更新表!AF:AF) -> 20 | DF4: =_xlfn.XLOOKUP(K4,数据更新表!Z:Z,数据更新表!AG:AG) -> #N/A | DG4: =_xlfn.XLOOKUP(L4,数据更新表!Z:Z,数据更新表!AD:AD) -> 702.95 | DH4: =_xlfn.XLOOKUP(L4,数据更新表!Z:Z,数据更新表!AA:AA) -> 10833 | DI4: =_xlfn.XLOOKUP(L4,数据更新表!Z:Z,数据更新表!AB:AB) -> 132 | DJ4: =_xlfn.XLOOKUP(L4,数据更新表!Z:Z,数据更新表!AC:AC) -> 2.28% | DK4: =_xlfn.XLOOKUP(L4,数据更新表!Z:Z,数据更新表!AI:AI) -> 1.53% | DL4: =_xlfn.XLOOKUP(L4,数据更新表!AL:AL,数据更新表!AM:AM) -> 1.56% | DM4: =_xlfn.XLOOKUP(L4,数据更新表!Z:Z,数据更新表!AJ:AJ) -> 43.78 | DN4: 20 | DO4: 关 | DP4: Medical trolley | DQ4: 46052 | DU4: 独家 | DZ4: 1458升1558 | EE4: 1558 | EF4: =EE4/0.7 -> 2225.7143 | EG4: 105 | EH4: =EJ4/(EI4+EL4) -> 0.28750142 | EI4: =EG4*$EI$1 -> 274.05 | EJ4: =EE4-EI4-EL4-EO4-EN4-EP4-EQ4 -> 190.6685 | EK4: =EJ4/EE4 -> 0.1223803 | EL4: =EX4*2500*$EI$1 -> 389.1415 | EM4: =IF(EE4>299,"是","否") -> 是 | EN4: =EE4*0.05 -> 77.9 | EO4: =EE4*0.175 -> 272.65 | EP4: =IF(EE4<299,IF(EE4<99,25,IF(EE4<=149,30,IF(EE4<=299,37,85))),IF(EE4<=498,_xlfn.XLOOKUP(EW4,运费表!A:A,运费表!C:C,"重量超限",-1),_xlfn.XLOOKUP(EW4,运费表!A:A,运费表!D:D,"重量超限",-1))) -> 190 | EQ4: =EE4*0.105 -> 163.59 | ER4: =_xlfn.XLOOKUP(K4,[4]目录表!$H:$H,[4]目录表!$X:$X) -> 6.4 | ES4: =_xlfn.XLOOKUP(K4,[4]目录表!$H:$H,[4]目录表!$Y:$Y) -> 80 | ET4: =_xlfn.XLOOKUP(K4,[4]目录表!$H:$H,[4]目录表!$Z:$Z) -> 43 | EU4: =_xlfn.XLOOKUP(K4,[4]目录表!$H:$H,[4]目录表!$AA:$AA) -> 19 | EV4: =ES4*ET4*EU4/5000 -> 13.072 | EW4: =IF(EV4>=ER4,EV4,ER4) -> 13.072 | EX4: =_xlfn.XLOOKUP(K4,[2]目录表!$H:$H,[2]目录表!$AB:$AB) -> 0.059638544 | EZ4: =CZ4/7 -> 4.4285714 | FK4: =_xlfn.XLOOKUP(K4,[2]目录表!$H:$H,[2]目录表!$AJ:$AJ) -> 装柜
B5: Mesa Pasteur Con Cajon Rodable Uso Rudo Envío Gratis | Envío gratis (mercadolibre.com.mx) | C5: 7 | D5: 37 | E5: 45889 | G5: 麻醉车 | H5: 麻醉车 | J5: Mesa Pasteur Con Cajon Rodable Uso Rudo Envío Gratis | K5: XQ5-MZC | L5: 2515489727 | M5: 已上架 | N5: =_xlfn.XLOOKUP(L5,数据更新表!J:J,数据更新表!K:K) -> 100 | O5: =IFERROR(_xlfn.XLOOKUP(K5,数据更新表!A:A,数据更新表!B:B),"0") -> 37 | P5: =_xlfn.XLOOKUP(K5,[1]库销表!$F:$F,[1]库销表!$L:$L) -> 60 | Q5: =X5/W5 -> 479.5 | S5: =_xlfn.XLOOKUP(K5,数据更新表!R:R,数据更新表!S:S) -> #N/A | T5: =_xlfn.XLOOKUP(K5,数据更新表!V:V,数据更新表!W:W) -> #N/A | V5: =IFERROR(7*O5/CZ5,"0") -> 129.5 | W5: =CZ5/7 -> 0.28571429 | X5: =O5+P5+SUM(AH5:BQ5) -> 137 | AF5: =SUM(AG5:BQ5) -> 40 | AH5: 40 | BS5: =_xlfn.XLOOKUP(K5,[1]库销表!$F:$F,[1]库销表!$L:$L) -> 60 | BT5: =SUM(BU5:CV5) -> 0 | CW5: =_xlfn.XLOOKUP(K5,[1]库销表!$F:$F,[1]库销表!$IE:$IE) -> 0 | CX5: =_xlfn.XLOOKUP(K5,[1]库销表!$F:$F,[1]库销表!$IF:$IF) -> 0 | CY5: =_xlfn.XLOOKUP(K5,[1]库销表!$F:$F,[1]库销表!$FL:$FL) -> 0 | CZ5: =_xlfn.XLOOKUP(K5,数据更新表!E:E,数据更新表!F:F,0) -> 2 | DA5: 0 | DB5: =_xlfn.XLOOKUP(K5,数据更新表!E:E,数据更新表!G:G) -> 1 | DC5: =_xlfn.XLOOKUP(L5,数据更新表!Z:Z,数据更新表!AH:AH) -> 2 | DD5: =_xlfn.XLOOKUP(L5,数据更新表!Z:Z,数据更新表!AE:AE) -> 0 | DE5: =_xlfn.XLOOKUP(L5,数据更新表!Z:Z,数据更新表!AF:AF) -> 0 | DF5: =_xlfn.XLOOKUP(K5,数据更新表!Z:Z,数据更新表!AG:AG) -> #N/A | DG5: =_xlfn.XLOOKUP(L5,数据更新表!Z:Z,数据更新表!AD:AD) -> 346.04 | DH5: =_xlfn.XLOOKUP(L5,数据更新表!Z:Z,数据更新表!AA:AA) -> 5564 | DI5: =_xlfn.XLOOKUP(L5,数据更新表!Z:Z,数据更新表!AB:AB) -> 41 | DJ5: =_xlfn.XLOOKUP(L5,数据更新表!Z:Z,数据更新表!AC:AC) -> 0.00% | DK5: =_xlfn.XLOOKUP(L5,数据更新表!Z:Z,数据更新表!AI:AI) -> 7.15% | DL5: =_xlfn.XLOOKUP(L5,数据更新表!AL:AL,数据更新表!AM:AM) -> 7.15% | DM5: =_xlfn.XLOOKUP(L5,数据更新表!Z:Z,数据更新表!AJ:AJ) -> 0 | DN5: 20 | DO5: 开 | DP5: Medical trolley | DX5: 2420降2398 | EE5: 2398 | EF5: =EE5/0.7 -> 3425.7143 | EG5: 180 | EH5: =EJ5/(EI5+EL5) -> 0.30928293 | EI5: =EG5*$EI$1 -> 469.8 | EJ5: =EE5-EI5-EL5-EO5-EN5-EP5-EQ5 -> 326.97063 | EK5: =EJ5/EE5 -> 0.13635139 | EL5: =EX5*2500*$EI$1 -> 587.38937 | EM5: =IF(EE5>299,"是","否") -> 是 | EN5: =EE5*0.05 -> 119.9 | EO5: =EE5*0.175 -> 419.65 | EP5: =IF(EE5<299,IF(EE5<99,25,IF(EE5<=149,30,IF(EE5<=299,37,85))),IF(EE5<=498,_xlfn.XLOOKUP(EW5,运费表!A:A,运费表!C:C,"重量超限",-1),_xlfn.XLOOKUP(EW5,运费表!A:A,运费表!D:D,"重量超限",-1))) -> 222.5 | EQ5: =EE5*0.105 -> 251.79 | ER5: =_xlfn.XLOOKUP(K5,[4]目录表!$H:$H,[4]目录表!$X:$X) -> 8.4 | ES5: =_xlfn.XLOOKUP(K5,[4]目录表!$H:$H,[4]目录表!$Y:$Y) -> 59 | ET5: =_xlfn.XLOOKUP(K5,[4]目录表!$H:$H,[4]目录表!$Z:$Z) -> 43 | EU5: =_xlfn.XLOOKUP(K5,[4]目录表!$H:$H,[4]目录表!$AA:$AA) -> 38 | EV5: =ES5*ET5*EU5/5000 -> 19.2812 | EW5: =IF(EV5>=ER5,EV5,ER5) -> 19.2812 | EX5: =_xlfn.XLOOKUP(K5,[2]目录表!$H:$H,[2]目录表!$AB:$AB) -> 0.09002136 | EZ5: =CZ5/7 -> 0.28571429 | FK5: =_xlfn.XLOOKUP(K5,[2]目录表!$H:$H,[2]目录表!$AJ:$AJ) -> 装柜
B6: Mesa Mayo Con Charola Acero Inoxidable Ajustable Uso Rudo | Envío gratis (mercadolibre.com.mx) | C6: 16 | D6: 18 | E6: 45889 | G6: 托盘架 | H6: 四脚托盘架-45*35 | J6: Mesa Mayo Con Charola Acero Inoxidable Ajustable Uso Rudo | K6: XQ5-SJTPJ-45*35 | L6: 2515701467 | M6: 已上架 | N6: =_xlfn.XLOOKUP(L6,数据更新表!J:J,数据更新表!K:K) -> 65 | O6: =IFERROR(_xlfn.XLOOKUP(K6,数据更新表!A:A,数据更新表!B:B),"0") -> 36 | P6: =_xlfn.XLOOKUP(K6,[1]库销表!$F:$F,[1]库销表!$L:$L) -> 60 | Q6: =X6/W6 -> 238 | S6: =_xlfn.XLOOKUP(K6,数据更新表!R:R,数据更新表!S:S) -> #N/A | T6: =_xlfn.XLOOKUP(K6,数据更新表!V:V,数据更新表!W:W) -> #N/A | V6: =IFERROR(7*O6/CZ6,"0") -> 63 | W6: =CZ6/7 -> 0.57142857 | X6: =O6+P6+SUM(AH6:BQ6) -> 136 | AF6: =SUM(AG6:BQ6) -> 40 | AH6: 40 | BS6: =_xlfn.XLOOKUP(K6,[1]库销表!$F:$F,[1]库销表!$L:$L) -> 60 | BT6: =SUM(BU6:CV6) -> 0 | CW6: =_xlfn.XLOOKUP(K6,[1]库销表!$F:$F,[1]库销表!$IE:$IE) -> 0 | CX6: =_xlfn.XLOOKUP(K6,[1]库销表!$F:$F,[1]库销表!$IF:$IF) -> 0 | CY6: =_xlfn.XLOOKUP(K6,[1]库销表!$F:$F,[1]库销表!$FL:$FL) -> 0 | CZ6: =_xlfn.XLOOKUP(K6,数据更新表!E:E,数据更新表!F:F,0) -> 4 | DA6: 0 | DB6: =_xlfn.XLOOKUP(K6,数据更新表!E:E,数据更新表!G:G) -> 0 | DC6: =_xlfn.XLOOKUP(L6,数据更新表!Z:Z,数据更新表!AH:AH) -> 0 | DD6: =_xlfn.XLOOKUP(L6,数据更新表!Z:Z,数据更新表!AE:AE) -> 4 | DE6: =_xlfn.XLOOKUP(L6,数据更新表!Z:Z,数据更新表!AF:AF) -> 3 | DF6: =_xlfn.XLOOKUP(K6,数据更新表!Z:Z,数据更新表!AG:AG) -> #N/A | DG6: =_xlfn.XLOOKUP(L6,数据更新表!Z:Z,数据更新表!AD:AD) -> 314.46 | DH6: =_xlfn.XLOOKUP(L6,数据更新表!Z:Z,数据更新表!AA:AA) -> 5804 | DI6: =_xlfn.XLOOKUP(L6,数据更新表!Z:Z,数据更新表!AB:AB) -> 53 | DJ6: =_xlfn.XLOOKUP(L6,数据更新表!Z:Z,数据更新表!AC:AC) -> 6.93% | DK6: =_xlfn.XLOOKUP(L6,数据更新表!Z:Z,数据更新表!AI:AI) -> 7.65% | DL6: =_xlfn.XLOOKUP(L6,数据更新表!AL:AL,数据更新表!AM:AM) -> 7.65% | DM6: =_xlfn.XLOOKUP(L6,数据更新表!Z:Z,数据更新表!AJ:AJ) -> 14.44 | DN6: 20 | DO6: 开 | DP6: Medical trolley | EE6: 1090 | EF6: =_xlfn.XLOOKUP(L6,数据更新表!J:J,数据更新表!M:M) -> 1369.4 | EG6: 78 | EH6: =EJ6/(EI6+EL6) -> 0.18662614 | EI6: =EG6*$EI$1 -> 203.58 | EJ6: =EE6-EI6-EL6-EO6-EN6-EP6-EQ6 -> 89.457788 | EK6: =EJ6/EE6 -> 0.082071365 | EL6: =EX6*2500*$EI$1 -> 275.76221 | EM6: =IF(EE6>299,"是","否") -> 是 | EN6: =EE6*0.05 -> 54.5 | EO6: =EE6*0.175 -> 190.75 | EP6: =IF(EE6<299,IF(EE6<99,25,IF(EE6<=149,30,IF(EE6<=299,37,85))),IF(EE6<=498,_xlfn.XLOOKUP(EW6,运费表!A:A,运费表!C:C,"重量超限",-1),_xlfn.XLOOKUP(EW6,运费表!A:A,运费表!D:D,"重量超限",-1))) -> 161.5 | EQ6: =EE6*0.105 -> 114.45 | ER6: =_xlfn.XLOOKUP(K6,[4]目录表!$H:$H,[4]目录表!$X:$X) -> 4.2 | ES6: =_xlfn.XLOOKUP(K6,[4]目录表!$H:$H,[4]目录表!$Y:$Y) -> 81 | ET6: =_xlfn.XLOOKUP(K6,[4]目录表!$H:$H,[4]目录表!$Z:$Z) -> 46 | EU6: =_xlfn.XLOOKUP(K6,[4]目录表!$H:$H,[4]目录表!$AA:$AA) -> 13 | EV6: =ES6*ET6*EU6/5000 -> 9.6876 | EW6: =IF(EV6>=ER6,EV6,ER6) -> 9.6876 | EX6: =_xlfn.XLOOKUP(K6,[2]目录表!$H:$H,[2]目录表!$AB:$AB) -> 0.042262408 | EZ6: =CZ6/7 -> 0.57142857 | FK6: =_xlfn.XLOOKUP(K6,[2]目录表!$H:$H,[2]目录表!$AJ:$AJ) -> 装柜
B7: Andadera Ortopedica de Doble Apoyo para Adulto Andador Ortopédico de Aluminio Plegable Soporta 100kg Tikun Color Negro | Envío gratis (mercadolibre.com.mx) | C7: 75 | D7: 341 | E7: 45889 | G7: 助行器 | H7: 双弯助行器 | J7: Andadera Ortopedica De Doble Apoyo Para Adulto Soporta 100kg | K7: XQ5-SWZXQ | L7: 4238819076 | M7: 已上架 | N7: =_xlfn.XLOOKUP(L7,数据更新表!J:J,数据更新表!K:K) -> 100 | O7: =IFERROR(_xlfn.XLOOKUP(K7,数据更新表!A:A,数据更新表!B:B),"0") -> 10 | P7: =_xlfn.XLOOKUP(K7,[1]库销表!$F:$F,[1]库销表!$L:$L) -> 0 | Q7: =X7/W7 -> 35 | S7: =_xlfn.XLOOKUP(K7,数据更新表!R:R,数据更新表!S:S) -> #N/A | T7: =_xlfn.XLOOKUP(K7,数据更新表!V:V,数据更新表!W:W) -> #N/A | V7: =IFERROR(7*O7/CZ7,"0") -> 35 | W7: =CZ7/7 -> 0.28571429 | X7: =O7+P7+SUM(BN7:BR7) -> 10 | AF7: =SUM(AG7:BQ7) -> 0 | BS7: =_xlfn.XLOOKUP(K7,[1]库销表!$F:$F,[1]库销表!$L:$L) -> 0 | BT7: =SUM(BU7:CV7) -> 0 | CW7: =_xlfn.XLOOKUP(K7,[1]库销表!$F:$F,[1]库销表!$IE:$IE) -> 0 | CX7: =_xlfn.XLOOKUP(K7,[1]库销表!$F:$F,[1]库销表!$IF:$IF) -> 0 | CY7: =_xlfn.XLOOKUP(K7,[1]库销表!$F:$F,[1]库销表!$FL:$FL) -> 0 | CZ7: =_xlfn.XLOOKUP(K7,数据更新表!E:E,数据更新表!F:F,0) -> 2 | DA7: 4 | DB7: =_xlfn.XLOOKUP(K7,数据更新表!E:E,数据更新表!G:G) -> 0 | DC7: =_xlfn.XLOOKUP(L7,数据更新表!Z:Z,数据更新表!AH:AH) -> 2 | DD7: =_xlfn.XLOOKUP(L7,数据更新表!Z:Z,数据更新表!AE:AE) -> 0 | DE7: =_xlfn.XLOOKUP(L7,数据更新表!Z:Z,数据更新表!AF:AF) -> 0 | DF7: =_xlfn.XLOOKUP(K7,数据更新表!Z:Z,数据更新表!AG:AG) -> #N/A | DG7: =_xlfn.XLOOKUP(L7,数据更新表!Z:Z,数据更新表!AD:AD) -> 28.89 | DH7: =_xlfn.XLOOKUP(L7,数据更新表!Z:Z,数据更新表!AA:AA) -> 30981 | DI7: =_xlfn.XLOOKUP(L7,数据更新表!Z:Z,数据更新表!AB:AB) -> 13 | DJ7: =_xlfn.XLOOKUP(L7,数据更新表!Z:Z,数据更新表!AC:AC) -> 0.00% | DK7: =_xlfn.XLOOKUP(L7,数据更新表!Z:Z,数据更新表!AI:AI) -> 2.08% | DL7: =_xlfn.XLOOKUP(L7,数据更新表!AL:AL,数据更新表!AM:AM) -> 3.91% | DM7: =_xlfn.XLOOKUP(L7,数据更新表!Z:Z,数据更新表!AJ:AJ) -> 0 | DN7: 20 | DO7: 开 | DP7: walking aid_3 | DQ7: 46074 | DU7: 价优 无优势 清 | EE7: 696 | EF7: =EE7/0.7 -> 994.28571 | EG7: 34.5 | EH7: =EJ7/(EI7+EL7) -> -0.008631628 | EI7: =EG7*$EI$1 -> 90.045 | EJ7: =EE7-EI7-EL7-EO7-EN7-EP7-EQ7 -> -2.8455504 | EK7: =EJ7/EE7 -> -0.0040884345 | EL7: =EX7*2500*$EI$1 -> 239.62055 | EM7: =IF(EE7>299,"是","否") -> 是 | EN7: =EE7*0.05 -> 34.8 | EO7: =EE7*0.175 -> 121.8 | EP7: =IF(EE7<299,IF(EE7<99,25,IF(EE7<=149,30,IF(EE7<=299,37,85))),IF(EE7<=498,_xlfn.XLOOKUP(EW7,运费表!A:A,运费表!C:C,"重量超限",-1),_xlfn.XLOOKUP(EW7,运费表!A:A,运费表!D:D,"重量超限",-1))) -> 139.5 | EQ7: =EE7*0.105 -> 73.08 | ER7: =_xlfn.XLOOKUP(K7,[4]目录表!$H:$H,[4]目录表!$X:$X) -> 3 | ES7: =_xlfn.XLOOKUP(K7,[4]目录表!$H:$H,[4]目录表!$Y:$Y) -> 75.6 | ET7: =_xlfn.XLOOKUP(K7,[4]目录表!$H:$H,[4]目录表!$Z:$Z) -> 55.2 | EU7: =_xlfn.XLOOKUP(K7,[4]目录表!$H:$H,[4]目录表!$AA:$AA) -> 8.8 | EV7: =ES7*ET7*EU7/5000 -> 7.3446912 | EW7: =IF(EV7>=ER7,EV7,ER7) -> 7.3446912 | EX7: =_xlfn.XLOOKUP(K7,[2]目录表!$H:$H,[2]目录表!$AB:$AB) -> 0.036723456 | EZ7: =CZ7/7 -> 0.28571429 | FK7: =_xlfn.XLOOKUP(K7,[2]目录表!$H:$H,[2]目录表!$AJ:$AJ) -> 装柜
B8: Andadera Ortopédica Fija Tikun Para Adulto Plegable De Aluminio Negro | Envío gratis (mercadolibre.com.mx) | C8: 26 | D8: 202 | E8: 45889 | G8: 助行器 | H8: 单弯助行器 | J8: Andadera Ortopédica Fija De Aluminio Plegable Color Negro | K8: XQ5-DWZXQ | L8: 4239173046 | M8: 已上架 | N8: =_xlfn.XLOOKUP(L8,数据更新表!J:J,数据更新表!K:K) -> #N/A | O8: =IFERROR(_xlfn.XLOOKUP(K8,数据更新表!A:A,数据更新表!B:B),"0") -> 0 | P8: =_xlfn.XLOOKUP(K8,[1]库销表!$F:$F,[1]库销表!$L:$L) -> 0 | Q8: =X8/W8 -> #DIV/0! | S8: =_xlfn.XLOOKUP(K8,数据更新表!R:R,数据更新表!S:S) -> 12 | T8: =_xlfn.XLOOKUP(K8,数据更新表!V:V,数据更新表!W:W) -> #N/A | V8: =IFERROR(7*O8/CZ8,"0") -> 0 | W8: =CZ8/7 -> 0 | X8: =O8+P8+SUM(BN8:BR8) -> 0 | AF8: =SUM(AG8:BQ8) -> 0 | BS8: =_xlfn.XLOOKUP(K8,[1]库销表!$F:$F,[1]库销表!$L:$L) -> 0 | BT8: =SUM(BU8:CV8) -> 0 | CW8: =_xlfn.XLOOKUP(K8,[1]库销表!$F:$F,[1]库销表!$IE:$IE) -> 0 | CX8: =_xlfn.XLOOKUP(K8,[1]库销表!$F:$F,[1]库销表!$IF:$IF) -> 0 | CY8: =_xlfn.XLOOKUP(K8,[1]库销表!$F:$F,[1]库销表!$FL:$FL) -> 0 | CZ8: =_xlfn.XLOOKUP(K8,数据更新表!E:E,数据更新表!F:F,0) -> 0 | DA8: 0 | DB8: =_xlfn.XLOOKUP(K8,数据更新表!E:E,数据更新表!G:G) -> #N/A | DC8: =_xlfn.XLOOKUP(L8,数据更新表!Z:Z,数据更新表!AH:AH) -> #N/A | DD8: =_xlfn.XLOOKUP(L8,数据更新表!Z:Z,数据更新表!AE:AE) -> #N/A | DE8: =_xlfn.XLOOKUP(L8,数据更新表!Z:Z,数据更新表!AF:AF) -> #N/A | DF8: =_xlfn.XLOOKUP(K8,数据更新表!Z:Z,数据更新表!AG:AG) -> #N/A | DG8: =_xlfn.XLOOKUP(L8,数据更新表!Z:Z,数据更新表!AD:AD) -> #N/A | DH8: =_xlfn.XLOOKUP(L8,数据更新表!Z:Z,数据更新表!AA:AA) -> #N/A | DI8: =_xlfn.XLOOKUP(L8,数据更新表!Z:Z,数据更新表!AB:AB) -> #N/A | DJ8: =_xlfn.XLOOKUP(L8,数据更新表!Z:Z,数据更新表!AC:AC) -> #N/A | DK8: =_xlfn.XLOOKUP(L8,数据更新表!Z:Z,数据更新表!AI:AI) -> #N/A | DL8: =_xlfn.XLOOKUP(L8,数据更新表!AL:AL,数据更新表!AM:AM) -> 11.79% | DM8: =_xlfn.XLOOKUP(L8,数据更新表!Z:Z,数据更新表!AJ:AJ) -> #N/A | DN8: 10 | DO8: 已禁用 | DP8: walking aid_1 | DQ8: 46074 | EE8: =_xlfn.XLOOKUP(L8,数据更新表!J:J,数据更新表!L:L) -> #N/A | EF8: =_xlfn.XLOOKUP(L8,数据更新表!J:J,数据更新表!M:M) -> #N/A | EG8: 30.5 | EH8: =EJ8/(EI8+EL8) -> #N/A | EI8: =EG8*$EI$1 -> 79.605 | EJ8: =EE8-EI8-EL8-EO8-EN8-EP8-EQ8 -> #N/A | EK8: =EJ8/EE8 -> #N/A | EL8: =EX8*2500*$EI$1 -> 222.67476 | EM8: =IF(EE8>299,"是","否") -> #N/A | EN8: =EE8*0.05 -> #N/A | EO8: =EE8*0.175 -> #N/A | EP8: =IF(EE8<299,IF(EE8<99,25,IF(EE8<=149,30,IF(EE8<=299,37,85))),IF(EE8<=498,_xlfn.XLOOKUP(EW8,运费表!A:A,运费表!C:C,"重量超限",-1),_xlfn.XLOOKUP(EW8,运费表!A:A,运费表!D:D,"重量超限",-1))) -> #N/A | EQ8: =EE8*0.105 -> #N/A | ER8: =_xlfn.XLOOKUP(K8,[4]目录表!$H:$H,[4]目录表!$X:$X) -> 2.8 | ES8: =_xlfn.XLOOKUP(K8,[4]目录表!$H:$H,[4]目录表!$Y:$Y) -> 77 | ET8: =_xlfn.XLOOKUP(K8,[4]目录表!$H:$H,[4]目录表!$Z:$Z) -> 55.4 | EU8: =_xlfn.XLOOKUP(K8,[4]目录表!$H:$H,[4]目录表!$AA:$AA) -> 8 | EV8: =ES8*ET8*EU8/5000 -> 6.82528 | EW8: =IF(EV8>=ER8,EV8,ER8) -> 6.82528 | EX8: =_xlfn.XLOOKUP(K8,[2]目录表!$H:$H,[2]目录表!$AB:$AB) -> 0.0341264 | EZ8: =CZ8/7 -> 0 | FK8: =_xlfn.XLOOKUP(K8,[2]目录表!$H:$H,[2]目录表!$AJ:$AJ) -> 装柜
B9: Andadera ortopédica con ruedas Dewinner HS-ZLQ color plateado | Envío gratis (mercadolibre.com.mx) | C9: 51 | D9: 275 | E9: 45889 | G9: 助行器 | H9: 双弯带轮带板助行器 | J9: Andadera ortopédica con ruedas Dewinner HS-ZLQ color plateado | K9: XQ5-SWDLDBZXQ | L9: 4239812144 | M9: 已上架 | N9: =_xlfn.XLOOKUP(L9,数据更新表!J:J,数据更新表!K:K) -> #N/A | O9: =IFERROR(_xlfn.XLOOKUP(K9,数据更新表!A:A,数据更新表!B:B),"0") -> 0 | P9: =_xlfn.XLOOKUP(K9,[1]库销表!$F:$F,[1]库销表!$L:$L) -> 0 | Q9: =X9/W9 -> #DIV/0! | S9: =_xlfn.XLOOKUP(K9,数据更新表!R:R,数据更新表!S:S) -> #N/A | T9: =_xlfn.XLOOKUP(K9,数据更新表!V:V,数据更新表!W:W) -> #N/A | V9: =IFERROR(7*O9/CZ9,"0") -> 0 | W9: =CZ9/7 -> 0 | X9: =O9+P9+SUM(BN9:BR9) -> 0 | AF9: =SUM(AG9:BQ9) -> 0 | BS9: =_xlfn.XLOOKUP(K9,[1]库销表!$F:$F,[1]库销表!$L:$L) -> 0 | BT9: =SUM(BU9:CV9) -> 0 | CW9: =_xlfn.XLOOKUP(K9,[1]库销表!$F:$F,[1]库销表!$IE:$IE) -> 0 | CX9: =_xlfn.XLOOKUP(K9,[1]库销表!$F:$F,[1]库销表!$IF:$IF) -> 0 | CY9: =_xlfn.XLOOKUP(K9,[1]库销表!$F:$F,[1]库销表!$FL:$FL) -> 0 | CZ9: =_xlfn.XLOOKUP(K9,数据更新表!E:E,数据更新表!F:F,0) -> 0 | DA9: 0 | DB9: =_xlfn.XLOOKUP(K9,数据更新表!E:E,数据更新表!G:G) -> #N/A | DC9: =_xlfn.XLOOKUP(L9,数据更新表!Z:Z,数据更新表!AH:AH) -> #N/A | DD9: =_xlfn.XLOOKUP(L9,数据更新表!Z:Z,数据更新表!AE:AE) -> #N/A | DE9: =_xlfn.XLOOKUP(L9,数据更新表!Z:Z,数据更新表!AF:AF) -> #N/A | DF9: =_xlfn.XLOOKUP(K9,数据更新表!Z:Z,数据更新表!AG:AG) -> #N/A | DG9: =_xlfn.XLOOKUP(L9,数据更新表!Z:Z,数据更新表!AD:AD) -> #N/A | DH9: =_xlfn.XLOOKUP(L9,数据更新表!Z:Z,数据更新表!AA:AA) -> #N/A | DI9: =_xlfn.XLOOKUP(L9,数据更新表!Z:Z,数据更新表!AB:AB) -> #N/A | DJ9: =_xlfn.XLOOKUP(L9,数据更新表!Z:Z,数据更新表!AC:AC) -> #N/A | DK9: =_xlfn.XLOOKUP(L9,数据更新表!Z:Z,数据更新表!AI:AI) -> #N/A | DL9: =_xlfn.XLOOKUP(L9,数据更新表!AL:AL,数据更新表!AM:AM) -> 7.90% | DM9: =_xlfn.XLOOKUP(L9,数据更新表!Z:Z,数据更新表!AJ:AJ) -> #N/A | DN9: 10 | DO9: 已禁用 | DP9: walking aid_2 | DQ9: 46074 | DU9: 价高 同958 | EE9: =_xlfn.XLOOKUP(L9,数据更新表!J:J,数据更新表!L:L) -> #N/A | EF9: =_xlfn.XLOOKUP(L9,数据更新表!J:J,数据更新表!M:M) -> #N/A | EG9: 51.5 | EH9: =EJ9/(EI9+EL9) -> #N/A | EI9: =EG9*$EI$1 -> 134.415 | EJ9: =EE9-EI9-EL9-EO9-EN9-EP9-EQ9 -> #N/A | EK9: =EJ9/EE9 -> #N/A | EL9: =EX9*2500*$EI$1 -> 266.31814 | EM9: =IF(EE9>299,"是","否") -> #N/A | EN9: =EE9*0.05 -> #N/A | EO9: =EE9*0.175 -> #N/A | EP9: =IF(EE9<299,IF(EE9<99,25,IF(EE9<=149,30,IF(EE9<=299,37,85))),IF(EE9<=498,_xlfn.XLOOKUP(EW9,运费表!A:A,运费表!C:C,"重量超限",-1),_xlfn.XLOOKUP(EW9,运费表!A:A,运费表!D:D,"重量超限",-1))) -> #N/A | EQ9: =EE9*0.105 -> #N/A | ER9: =_xlfn.XLOOKUP(K9,[4]目录表!$H:$H,[4]目录表!$X:$X) -> 4.4 | ES9: =_xlfn.XLOOKUP(K9,[4]目录表!$H:$H,[4]目录表!$Y:$Y) -> 76 | ET9: =_xlfn.XLOOKUP(K9,[4]目录表!$H:$H,[4]目录表!$Z:$Z) -> 54.8 | EU9: =_xlfn.XLOOKUP(K9,[4]目录表!$H:$H,[4]目录表!$AA:$AA) -> 9.8 | EV9: =ES9*ET9*EU9/5000 -> 8.163008 | EW9: =IF(EV9>=ER9,EV9,ER9) -> 8.163008 | EX9: =_xlfn.XLOOKUP(K9,[2]目录表!$H:$H,[2]目录表!$AB:$AB) -> 0.04081504 | EZ9: =CZ9/7 -> 0 | FK9: =_xlfn.XLOOKUP(K9,[2]目录表!$H:$H,[2]目录表!$AJ:$AJ) -> 装柜
B10: Porta Sueros Acero Inox 3 Ruedas Base De Hierro Con Cubierta | Meses sin interés (mercadolibre.com.mx) | C10: 14 | D10: 46 | E10: 45889 | G10: 输液架 | H10: 输液架-折叠 | J10: Porta Sueros Acero Inox 3 Ruedas Base De Hierro Con Cubierta | K10: ZD-XQ5-SYJ | L10: 2515831365 | M10: 已上架 | N10: =_xlfn.XLOOKUP(L10,数据更新表!J:J,数据更新表!K:K) -> #N/A | O10: =IFERROR(_xlfn.XLOOKUP(K10,数据更新表!A:A,数据更新表!B:B),"0") -> 0 | P10: =_xlfn.XLOOKUP(K10,[1]库销表!$F:$F,[1]库销表!$L:$L) -> 0 | Q10: =X10/W10 -> 0 | S10: =_xlfn.XLOOKUP(K10,数据更新表!R:R,数据更新表!S:S) -> #N/A | T10: =_xlfn.XLOOKUP(K10,数据更新表!V:V,数据更新表!W:W) -> #N/A | V10: =IFERROR(7*O10/CZ10,"0") -> 0 | W10: =CZ10/7 -> 0.71428571 | X10: =O10+P10+SUM(BN10:BR10) -> 0 | AF10: =SUM(AG10:BQ10) -> 0 | BS10: =_xlfn.XLOOKUP(K10,[1]库销表!$F:$F,[1]库销表!$L:$L) -> 0 | BT10: =SUM(BU10:CV10) -> 0 | CW10: =_xlfn.XLOOKUP(K10,[1]库销表!$F:$F,[1]库销表!$IE:$IE) -> 0 | CX10: =_xlfn.XLOOKUP(K10,[1]库销表!$F:$F,[1]库销表!$IF:$IF) -> 0 | CY10: =_xlfn.XLOOKUP(K10,[1]库销表!$F:$F,[1]库销表!$FL:$FL) -> 0 | CZ10: =_xlfn.XLOOKUP(K10,数据更新表!E:E,数据更新表!F:F,0) -> 5 | DA10: 5 | DB10: =_xlfn.XLOOKUP(K10,数据更新表!E:E,数据更新表!G:G) -> 0 | DC10: =_xlfn.XLOOKUP(L10,数据更新表!Z:Z,数据更新表!AH:AH) -> 4 | DD10: =_xlfn.XLOOKUP(L10,数据更新表!Z:Z,数据更新表!AE:AE) -> 1 | DE10: =_xlfn.XLOOKUP(L10,数据更新表!Z:Z,数据更新表!AF:AF) -> 1 | DF10: =_xlfn.XLOOKUP(K10,数据更新表!Z:Z,数据更新表!AG:AG) -> #N/A | DG10: =_xlfn.XLOOKUP(L10,数据更新表!Z:Z,数据更新表!AD:AD) -> 36.96 | DH10: =_xlfn.XLOOKUP(L10,数据更新表!Z:Z,数据更新表!AA:AA) -> 3717 | DI10: =_xlfn.XLOOKUP(L10,数据更新表!Z:Z,数据更新表!AB:AB) -> 21 | DJ10: =_xlfn.XLOOKUP(L10,数据更新表!Z:Z,数据更新表!AC:AC) -> 8.05% | DK10: =_xlfn.XLOOKUP(L10,数据更新表!Z:Z,数据更新表!AI:AI) -> 1.61% | DL10: =_xlfn.XLOOKUP(L10,数据更新表!AL:AL,数据更新表!AM:AM) -> 1.61% | DM10: =_xlfn.XLOOKUP(L10,数据更新表!Z:Z,数据更新表!AJ:AJ) -> 12.42 | DN10: 10 | DO10: 开 | DP10: Ordinary items | DQ10: 46074 | DU10: 价高 无优势 | EE10: 459 | EF10: =EE10/0.7 -> 655.71429 | EG10: 50 | EH10: =EJ10/(EI10+EL10) -> 0.27744979 | EI10: =EG10*$EI$1 -> 130.5 | EJ10: =EE10-EI10-EL10-EO10-EN10-EP10-EQ10 -> 52.110485 | EK10: =EJ10/EE10 -> 0.11353047 | EL10: =EX10*3000*$EI$1 -> 57.319515 | EM10: =IF(EE10>299,"是","否") -> 是 | EN10: =EE10*0.05 -> 22.95 | EO10: =EE10*0.175 -> 80.325 | EP10: =IF(EE10<299,IF(EE10<99,25,IF(EE10<=149,30,IF(EE10<=299,37,85))),IF(EE10<=498,_xlfn.XLOOKUP(EW10,运费表!A:A,运费表!C:C,"重量超限",-1),_xlfn.XLOOKUP(EW10,运费表!A:A,运费表!D:D,"重量超限",-1))) -> 67.6 | EQ10: =EE10*0.105 -> 48.195 | ER10: =_xlfn.XLOOKUP(K10,[4]目录表!$H:$H,[4]目录表!$X:$X) -> 1.8 | ES10: =_xlfn.XLOOKUP(K10,[4]目录表!$H:$H,[4]目录表!$Y:$Y) -> 60.5 | ET10: =_xlfn.XLOOKUP(K10,[4]目录表!$H:$H,[4]目录表!$Z:$Z) -> 11 | EU10: =_xlfn.XLOOKUP(K10,[4]目录表!$H:$H,[4]目录表!$AA:$AA) -> 11 | EV10: =ES10*ET10*EU10/5000 -> 1.4641 | EW10: =IF(EV10>=ER10,EV10,ER10) -> 1.8 | EX10: =_xlfn.XLOOKUP(K10,[2]目录表!$H:$H,[2]目录表!$AB:$AB) -> 0.0073205 | EZ10: =CZ10/7 -> 0.71428571 | FK10: =_xlfn.XLOOKUP(K10,[2]目录表!$H:$H,[2]目录表!$AJ:$AJ) -> 散货
B11: Modulo Ventilador Para Mazda 3 5 Ford Focus Fusion Escape | Meses sin interés | C11: 15 | D11: 47 | E11: 46041 | G11: 风扇散热器 | H11: 风扇散热器1137328464 | J11: Modulo Ventilador Para Mazda 3 5 Ford Focus Fusion Escape | K11: XQ5-QP001-1137328464 | L11: 4683662970 | M11: 新上架 | N11: =_xlfn.XLOOKUP(L11,数据更新表!J:J,数据更新表!K:K) -> -- | O11: =IFERROR(_xlfn.XLOOKUP(K11,数据更新表!A:A,数据更新表!B:B),"0") -> 30 | P11: =_xlfn.XLOOKUP(K11,[1]库销表!$F:$F,[1]库销表!$L:$L) -> 0 | Q11: =X11/W11 -> #DIV/0! | S11: =_xlfn.XLOOKUP(K11,数据更新表!R:R,数据更新表!S:S) -> #N/A | T11: =_xlfn.XLOOKUP(K11,数据更新表!V:V,数据更新表!W:W) -> #N/A | V11: =IFERROR(7*O11/CZ11,"0") -> 0 | W11: =CZ11/7 -> 0 | X11: =O11+P11+SUM(BN11:BR11) -> 30 | AF11: =SUM(AG11:BQ11) -> 30 | AK11: 30 | BS11: =_xlfn.XLOOKUP(K11,[1]库销表!$F:$F,[1]库销表!$L:$L) -> 0 | BT11: =SUM(BU11:CV11) -> 0 | CW11: =_xlfn.XLOOKUP(K11,[1]库销表!$F:$F,[1]库销表!$IE:$IE) -> 0 | CX11: =_xlfn.XLOOKUP(K11,[1]库销表!$F:$F,[1]库销表!$IF:$IF) -> 0 | CY11: =_xlfn.XLOOKUP(K11,[1]库销表!$F:$F,[1]库销表!$FL:$FL) -> 0 | CZ11: =_xlfn.XLOOKUP(K11,数据更新表!E:E,数据更新表!F:F,0) -> 0 | DA11: 0 | DB11: =_xlfn.XLOOKUP(K11,数据更新表!E:E,数据更新表!G:G) -> #N/A | DC11: =_xlfn.XLOOKUP(L11,数据更新表!Z:Z,数据更新表!AH:AH) -> 0 | DD11: =_xlfn.XLOOKUP(L11,数据更新表!Z:Z,数据更新表!AE:AE) -> 0 | DE11: =_xlfn.XLOOKUP(L11,数据更新表!Z:Z,数据更新表!AF:AF) -> 0 | DF11: =_xlfn.XLOOKUP(K11,数据更新表!Z:Z,数据更新表!AG:AG) -> #N/A | DG11: =_xlfn.XLOOKUP(L11,数据更新表!Z:Z,数据更新表!AD:AD) -> 3.64 | DH11: =_xlfn.XLOOKUP(L11,数据更新表!Z:Z,数据更新表!AA:AA) -> 1495 | DI11: =_xlfn.XLOOKUP(L11,数据更新表!Z:Z,数据更新表!AB:AB) -> 2 | DJ11: =_xlfn.XLOOKUP(L11,数据更新表!Z:Z,数据更新表!AC:AC) -> 0.00% | DK11: =_xlfn.XLOOKUP(L11,数据更新表!Z:Z,数据更新表!AI:AI) -> 0.00% | DL11: =_xlfn.XLOOKUP(L11,数据更新表!AL:AL,数据更新表!AM:AM) -> 0.00% | DM11: =_xlfn.XLOOKUP(L11,数据更新表!Z:Z,数据更新表!AJ:AJ) -> 0 | DN11: 6.6 | DO11: 开 | DP11: san re_1 | DQ11: 46084 | DU11: 没权重，等广告清货 | DY11: 469降288 | ED11: 调474 开广 | EE11: 288 | EF11: =EE11/0.7 -> 411.42857 | EG11: 51 | EH11: =EJ11/(EI11+EL11) -> 0.11275213 | EI11: =EG11*$EI$1 -> 133.11 | EJ11: =EE11-EI11-EL11-EO11-EN11-EP11-EQ11 -> 15.803 | EK11: =EJ11/EE11 -> 0.054871528 | EL11: =EX11*3000*$EI$1 -> 7.047 | EM11: =IF(EE11>299,"是","否") -> 否 | EN11: =EE11*0.05 -> 14.4 | EO11: =EE11*0.175 -> 50.4 | EP11: =IF(EE11<299,IF(EE11<99,25,IF(EE11<=149,30,IF(EE11<=299,37,85))),IF(EE11<=498,_xlfn.XLOOKUP(EW11,运费表!A:A,运费表!C:C,"重量超限",-1),_xlfn.XLOOKUP(EW11,运费表!A:A,运费表!D:D,"重量超限",-1))) -> 37 | EQ11: =EE11*0.105 -> 30.24 | ER11: =_xlfn.XLOOKUP(K11,[4]目录表!$H:$H,[4]目录表!$X:$X) -> 0.3 | ES11: =_xlfn.XLOOKUP(K11,[4]目录表!$H:$H,[4]目录表!$Y:$Y) -> 0 | ET11: =_xlfn.XLOOKUP(K11,[4]目录表!$H:$H,[4]目录表!$Z:$Z) -> 0 | EU11: =_xlfn.XLOOKUP(K11,[4]目录表!$H:$H,[4]目录表!$AA:$AA) -> 0 | EV11: =(50*30*30)/50/5000 -> 0.18 | EW11: =IF(EV11>=ER11,EV11,ER11) -> 0.3 | EX11: =_xlfn.XLOOKUP(K11,[2]目录表!$H:$H,[2]目录表!$AB:$AB) -> 0.0009 | EZ11: =CZ11/7 -> 0 | FK11: =_xlfn.XLOOKUP(K11,[2]目录表!$H:$H,[2]目录表!$AJ:$AJ) -> 散货
B12: Modulo Moto Ventilador Ford Edge 3.5l 2007 Al 2015 | Envío gratis | C12: 0 | D12: 5 | E12: 46038 | G12: 风扇散热器 | H12: 风扇散热器4M519A810AA | J12: Modulo Moto Ventilador Ford Edge 3.5l 2007 Al 2015 | K12: XQ5-QP002-4M519A810AA | L12: 4683845582 | M12: 新上架 | N12: =_xlfn.XLOOKUP(L12,数据更新表!J:J,数据更新表!K:K) -> -- | O12: =IFERROR(_xlfn.XLOOKUP(K12,数据更新表!A:A,数据更新表!B:B),"0") -> 30 | P12: =_xlfn.XLOOKUP(K12,[1]库销表!$F:$F,[1]库销表!$L:$L) -> 0 | Q12: =X12/W12 -> #DIV/0! | S12: =_xlfn.XLOOKUP(K12,数据更新表!R:R,数据更新表!S:S) -> #N/A | T12: =_xlfn.XLOOKUP(K12,数据更新表!V:V,数据更新表!W:W) -> #N/A | V12: =IFERROR(7*O12/CZ12,"0") -> 0 | W12: =CZ12/7 -> 0 | X12: =O12+P12+SUM(BN12:BR12) -> 30 | AF12: =SUM(AG12:BQ12) -> 30 | AK12: 30 | BS12: =_xlfn.XLOOKUP(K12,[1]库销表!$F:$F,[1]库销表!$L:$L) -> 0 | BT12: =SUM(BU12:CV12) -> 0 | CW12: =_xlfn.XLOOKUP(K12,[1]库销表!$F:$F,[1]库销表!$IE:$IE) -> 0 | CX12: =_xlfn.XLOOKUP(K12,[1]库销表!$F:$F,[1]库销表!$IF:$IF) -> 0 | CY12: =_xlfn.XLOOKUP(K12,[1]库销表!$F:$F,[1]库销表!$FL:$FL) -> 0 | CZ12: =_xlfn.XLOOKUP(K12,数据更新表!E:E,数据更新表!F:F,0) -> 0 | DA12: 0 | DB12: =_xlfn.XLOOKUP(K12,数据更新表!E:E,数据更新表!G:G) -> #N/A | DC12: =_xlfn.XLOOKUP(L12,数据更新表!Z:Z,数据更新表!AH:AH) -> 0 | DD12: =_xlfn.XLOOKUP(L12,数据更新表!Z:Z,数据更新表!AE:AE) -> 0 | DE12: =_xlfn.XLOOKUP(L12,数据更新表!Z:Z,数据更新表!AF:AF) -> 0 | DF12: =_xlfn.XLOOKUP(K12,数据更新表!Z:Z,数据更新表!AG:AG) -> #N/A | DG12: =_xlfn.XLOOKUP(L12,数据更新表!Z:Z,数据更新表!AD:AD) -> 2.32 | DH12: =_xlfn.XLOOKUP(L12,数据更新表!Z:Z,数据更新表!AA:AA) -> 1860 | DI12: =_xlfn.XLOOKUP(L12,数据更新表!Z:Z,数据更新表!AB:AB) -> 2 | DJ12: =_xlfn.XLOOKUP(L12,数据更新表!Z:Z,数据更新表!AC:AC) -> 0.00% | DK12: =_xlfn.XLOOKUP(L12,数据更新表!Z:Z,数据更新表!AI:AI) -> 0.00% | DL12: =_xlfn.XLOOKUP(L12,数据更新表!AL:AL,数据更新表!AM:AM) -> 0.00% | DM12: =_xlfn.XLOOKUP(L12,数据更新表!Z:Z,数据更新表!AJ:AJ) -> 0 | DN12: 6.6 | DO12: 开 | DP12: san re_1 | DQ12: 46084 | DU12: 没权重，等广告清货 | ED12: 调636 开广 | EE12: 238 | EF12: =EE12/0.7 -> 340 | EG12: 43 | EH12: =EJ12/(EI12+EL12) -> 0.026685782 | EI12: =EG12*$EI$1 -> 112.23 | EJ12: =EE12-EI12-EL12-EO12-EN12-EP12-EQ12 -> 3.183 | EK12: =EJ12/EE12 -> 0.01337395 | EL12: =EX12*3000*$EI$1 -> 7.047 | EM12: =IF(EE12>299,"是","否") -> 否 | EN12: =EE12*0.05 -> 11.9 | EO12: =EE12*0.175 -> 41.65 | EP12: =IF(EE12<299,IF(EE12<99,25,IF(EE12<=149,30,IF(EE12<=299,37,85))),IF(EE12<=498,_xlfn.XLOOKUP(EW12,运费表!A:A,运费表!C:C,"重量超限",-1),_xlfn.XLOOKUP(EW12,运费表!A:A,运费表!D:D,"重量超限",-1))) -> 37 | EQ12: =EE12*0.105 -> 24.99 | ER12: =_xlfn.XLOOKUP(K12,[4]目录表!$H:$H,[4]目录表!$X:$X) -> 0.34 | ES12: =_xlfn.XLOOKUP(K12,[4]目录表!$H:$H,[4]目录表!$Y:$Y) -> 0 | ET12: =_xlfn.XLOOKUP(K12,[4]目录表!$H:$H,[4]目录表!$Z:$Z) -> 0 | EU12: =_xlfn.XLOOKUP(K12,[4]目录表!$H:$H,[4]目录表!$AA:$AA) -> 0 | EV12: =(50*30*30)/50/5000 -> 0.18 | EW12: =IF(EV12>=ER12,EV12,ER12) -> 0.34 | EX12: =_xlfn.XLOOKUP(K12,[2]目录表!$H:$H,[2]目录表!$AB:$AB) -> 0.0009 | EZ12: =CZ12/7 -> 0 | FK12: =_xlfn.XLOOKUP(K12,[2]目录表!$H:$H,[2]目录表!$AJ:$AJ) -> 散货
B13: Modulo Control Ventilador Focus 2 Mazda 3 Volvo C30 S40 V50 | Envío gratis | C13: 1 | D13: 2 | E13: 46038 | G13: 风扇散热器 | H13: 风扇散热器1137328365 | J13: Modulo Control Ventilador Focus 2 Mazda 3 Volvo C30 S40 V50 | K13: XQ5-QP003-1137328365 | L13: 4683730910 | M13: 新上架 | N13: =_xlfn.XLOOKUP(L13,数据更新表!J:J,数据更新表!K:K) -> -- | O13: =IFERROR(_xlfn.XLOOKUP(K13,数据更新表!A:A,数据更新表!B:B),"0") -> 30 | P13: =_xlfn.XLOOKUP(K13,[1]库销表!$F:$F,[1]库销表!$L:$L) -> 0 | Q13: =X13/W13 -> #DIV/0! | S13: =_xlfn.XLOOKUP(K13,数据更新表!R:R,数据更新表!S:S) -> #N/A | T13: =_xlfn.XLOOKUP(K13,数据更新表!V:V,数据更新表!W:W) -> #N/A | V13: =IFERROR(7*O13/CZ13,"0") -> 0 | W13: =CZ13/7 -> 0 | X13: =O13+P13+SUM(BN13:BR13) -> 30 | AF13: =SUM(AG13:BQ13) -> 30 | AK13: 30 | BS13: =_xlfn.XLOOKUP(K13,[1]库销表!$F:$F,[1]库销表!$L:$L) -> 0 | BT13: =SUM(BU13:CV13) -> 0 | CW13: =_xlfn.XLOOKUP(K13,[1]库销表!$F:$F,[1]库销表!$IE:$IE) -> 0 | CX13: =_xlfn.XLOOKUP(K13,[1]库销表!$F:$F,[1]库销表!$IF:$IF) -> 0 | CY13: =_xlfn.XLOOKUP(K13,[1]库销表!$F:$F,[1]库销表!$FL:$FL) -> 0 | CZ13: =_xlfn.XLOOKUP(K13,数据更新表!E:E,数据更新表!F:F,0) -> 0 | DA13: 0 | DB13: =_xlfn.XLOOKUP(K13,数据更新表!E:E,数据更新表!G:G) -> #N/A | DC13: =_xlfn.XLOOKUP(L13,数据更新表!Z:Z,数据更新表!AH:AH) -> 0 | DD13: =_xlfn.XLOOKUP(L13,数据更新表!Z:Z,数据更新表!AE:AE) -> 0 | DE13: =_xlfn.XLOOKUP(L13,数据更新表!Z:Z,数据更新表!AF:AF) -> 0 | DF13: =_xlfn.XLOOKUP(K13,数据更新表!Z:Z,数据更新表!AG:AG) -> #N/A | DG13: =_xlfn.XLOOKUP(L13,数据更新表!Z:Z,数据更新表!AD:AD) -> 1.81 | DH13: =_xlfn.XLOOKUP(L13,数据更新表!Z:Z,数据更新表!AA:AA) -> 1595 | DI13: =_xlfn.XLOOKUP(L13,数据更新表!Z:Z,数据更新表!AB:AB) -> 1 | DJ13: =_xlfn.XLOOKUP(L13,数据更新表!Z:Z,数据更新表!AC:AC) -> 0.00% | DK13: =_xlfn.XLOOKUP(L13,数据更新表!Z:Z,数据更新表!AI:AI) -> 0.00% | DL13: =_xlfn.XLOOKUP(L13,数据更新表!AL:AL,数据更新表!AM:AM) -> 0.00% | DM13: =_xlfn.XLOOKUP(L13,数据更新表!Z:Z,数据更新表!AJ:AJ) -> 0 | DN13: 9.98 | DO13: 开 | DP13: fengshan-1 | DQ13: 46084 | DU13: 清货 | DV13: 400降369 | DY13: 400降369 | ED13: 调949 开广 | EE13: 369 | EF13: =EE13/0.7 -> 527.14286 | EG13: 57 | EH13: =EJ13/(EI13+EL13) -> 0.19484995 | EI13: =EG13*$EI$1 -> 148.77 | EJ13: =EE13-EI13-EL13-EO13-EN13-EP13-EQ13 -> 31.1848 | EK13: =EJ13/EE13 -> 0.084511653 | EL13: =EX13*3000*$EI$1 -> 11.2752 | EM13: =IF(EE13>299,"是","否") -> 是 | EN13: =EE13*0.05 -> 18.45 | EO13: =EE13*0.175 -> 64.575 | EP13: =IF(EE13<299,IF(EE13<99,25,IF(EE13<=149,30,IF(EE13<=299,37,85))),IF(EE13<=498,_xlfn.XLOOKUP(EW13,运费表!A:A,运费表!C:C,"重量超限",-1),_xlfn.XLOOKUP(EW13,运费表!A:A,运费表!D:D,"重量超限",-1))) -> 56 | EQ13: =EE13*0.105 -> 38.745 | ER13: =_xlfn.XLOOKUP(K13,[4]目录表!$H:$H,[4]目录表!$X:$X) -> 0.3 | ES13: =_xlfn.XLOOKUP(K13,[4]目录表!$H:$H,[4]目录表!$Y:$Y) -> 0 | ET13: =_xlfn.XLOOKUP(K13,[4]目录表!$H:$H,[4]目录表!$Z:$Z) -> 0 | EU13: =_xlfn.XLOOKUP(K13,[4]目录表!$H:$H,[4]目录表!$AA:$AA) -> 0 | EV13: =(50*30*30)/50/5000 -> 0.18 | EW13: =IF(EV13>=ER13,EV13,ER13) -> 0.3 | EX13: =_xlfn.XLOOKUP(K13,[2]目录表!$H:$H,[2]目录表!$AB:$AB) -> 0.00144 | EZ13: =CZ13/7 -> 0 | FK13: =_xlfn.XLOOKUP(K13,[2]目录表!$H:$H,[2]目录表!$AJ:$AJ) -> 散货
B14: Modulo Ventilador Ford Land Rover Jaguar Volvo S60 Xc60 | Envío gratis | C14: 2 | D14: 17 | E14: 46041 | G14: 风扇散热器 | H14: 风扇散热器940009402 | J14: Modulo Ventilador Ford Land Rover Jaguar Volvo S60 Xc60 | K14: XQ5-QP004-940009402 | L14: 4683874212 | M14: 新上架 | N14: =_xlfn.XLOOKUP(L14,数据更新表!J:J,数据更新表!K:K) -> 100 | O14: =IFERROR(_xlfn.XLOOKUP(K14,数据更新表!A:A,数据更新表!B:B),"0") -> 27 | P14: =_xlfn.XLOOKUP(K14,[1]库销表!$F:$F,[1]库销表!$L:$L) -> 0 | Q14: =X14/W14 -> 189 | S14: =_xlfn.XLOOKUP(K14,数据更新表!R:R,数据更新表!S:S) -> #N/A | T14: =_xlfn.XLOOKUP(K14,数据更新表!V:V,数据更新表!W:W) -> #N/A | V14: =IFERROR(7*O14/CZ14,"0") -> 189 | W14: =CZ14/7 -> 0.14285714 | X14: =O14+P14+SUM(BN14:BR14) -> 27 | AF14: =SUM(AG14:BQ14) -> 30 | AK14: 30 | BS14: =_xlfn.XLOOKUP(K14,[1]库销表!$F:$F,[1]库销表!$L:$L) -> 0 | BT14: =SUM(BU14:CV14) -> 0 | CW14: =_xlfn.XLOOKUP(K14,[1]库销表!$F:$F,[1]库销表!$IE:$IE) -> 0 | CX14: =_xlfn.XLOOKUP(K14,[1]库销表!$F:$F,[1]库销表!$IF:$IF) -> 0 | CY14: =_xlfn.XLOOKUP(K14,[1]库销表!$F:$F,[1]库销表!$FL:$FL) -> 0 | CZ14: =_xlfn.XLOOKUP(K14,数据更新表!E:E,数据更新表!F:F,0) -> 1 | DA14: 1 | DB14: =_xlfn.XLOOKUP(K14,数据更新表!E:E,数据更新表!G:G) -> 0 | DC14: =_xlfn.XLOOKUP(L14,数据更新表!Z:Z,数据更新表!AH:AH) -> 0 | DD14: =_xlfn.XLOOKUP(L14,数据更新表!Z:Z,数据更新表!AE:AE) -> 1 | DE14: =_xlfn.XLOOKUP(L14,数据更新表!Z:Z,数据更新表!AF:AF) -> 1 | DF14: =_xlfn.XLOOKUP(K14,数据更新表!Z:Z,数据更新表!AG:AG) -> #N/A | DG14: =_xlfn.XLOOKUP(L14,数据更新表!Z:Z,数据更新表!AD:AD) -> 62.28 | DH14: =_xlfn.XLOOKUP(L14,数据更新表!Z:Z,数据更新表!AA:AA) -> 1120 | DI14: =_xlfn.XLOOKUP(L14,数据更新表!Z:Z,数据更新表!AB:AB) -> 14 | DJ14: =_xlfn.XLOOKUP(L14,数据更新表!Z:Z,数据更新表!AC:AC) -> 12.28% | DK14: =_xlfn.XLOOKUP(L14,数据更新表!Z:Z,数据更新表!AI:AI) -> 12.28% | DL14: =_xlfn.XLOOKUP(L14,数据更新表!AL:AL,数据更新表!AM:AM) -> 3.84% | DM14: =_xlfn.XLOOKUP(L14,数据更新表!Z:Z,数据更新表!AJ:AJ) -> 8.14 | DN14: 9.98 | DO14: 开 | DP14: fengshan-1 | DQ14: 46084 | ED14: 调507 开广 | EE14: =_xlfn.XLOOKUP(L14,数据更新表!J:J,数据更新表!L:L) -> 507 | EF14: =EE14/0.7 -> 724.28571 | EG14: 65 | EH14: =EJ14/(EI14+EL14) -> 0.52628511 | EI14: =EG14*$EI$1 -> 169.65 | EJ14: =EE14-EI14-EL14-EO14-EN14-EP14-EQ14 -> 92.993 | EK14: =EJ14/EE14 -> 0.18341815 | EL14: =EX14*3000*$EI$1 -> 7.047 | EM14: =IF(EE14>299,"是","否") -> 是 | EN14: =EE14*0.05 -> 25.35 | EO14: =EE14*0.175 -> 88.725 | EP14: =IF(EE14<299,IF(EE14<99,25,IF(EE14<=149,30,IF(EE14<=299,37,85))),IF(EE14<=498,_xlfn.XLOOKUP(EW14,运费表!A:A,运费表!C:C,"重量超限",-1),_xlfn.XLOOKUP(EW14,运费表!A:A,运费表!D:D,"重量超限",-1))) -> 70 | EQ14: =EE14*0.105 -> 53.235 | ER14: =_xlfn.XLOOKUP(K14,[4]目录表!$H:$H,[4]目录表!$X:$X) -> 0.38 | ES14: =_xlfn.XLOOKUP(K14,[4]目录表!$H:$H,[4]目录表!$Y:$Y) -> 0 | ET14: =_xlfn.XLOOKUP(K14,[4]目录表!$H:$H,[4]目录表!$Z:$Z) -> 0 | EU14: =_xlfn.XLOOKUP(K14,[4]目录表!$H:$H,[4]目录表!$AA:$AA) -> 0 | EV14: =(50*30*30)/50/5000 -> 0.18 | EW14: =IF(EV14>=ER14,EV14,ER14) -> 0.38 | EX14: =_xlfn.XLOOKUP(K14,[2]目录表!$H:$H,[2]目录表!$AB:$AB) -> 0.0009 | EZ14: =CZ14/7 -> 0.14285714 | FK14: =_xlfn.XLOOKUP(K14,[2]目录表!$H:$H,[2]目录表!$AJ:$AJ) -> 散货
B15: Módulo Ventilador Ford Fusion Lincoln Mkz 3.5 2010 2011 2012 | Envío gratis | C15: 0 | D15: 4 | E15: 46038 | G15: 风扇散热器 | H15: 风扇散热器1137328617 | J15: Módulo Ventilador Ford Fusion Lincoln Mkz 3.5 2010 2011 2012 | K15: XQ5-QP005-1137328617 | L15: 4683876182 | M15: 新上架 | N15: =_xlfn.XLOOKUP(L15,数据更新表!J:J,数据更新表!K:K) -> -- | O15: =IFERROR(_xlfn.XLOOKUP(K15,数据更新表!A:A,数据更新表!B:B),"0") -> 19 | P15: =_xlfn.XLOOKUP(K15,[1]库销表!$F:$F,[1]库销表!$L:$L) -> 0 | Q15: =X15/W15 -> #DIV/0! | S15: =_xlfn.XLOOKUP(K15,数据更新表!R:R,数据更新表!S:S) -> #N/A | T15: =_xlfn.XLOOKUP(K15,数据更新表!V:V,数据更新表!W:W) -> #N/A | V15: =IFERROR(7*O15/CZ15,"0") -> 0 | W15: =CZ15/7 -> 0 | X15: =O15+P15+SUM(BN15:BR15) -> 19 | AF15: =SUM(AG15:BQ15) -> 19 | AK15: 19 | BS15: =_xlfn.XLOOKUP(K15,[1]库销表!$F:$F,[1]库销表!$L:$L) -> 0 | BT15: =SUM(BU15:CV15) -> 0 | CW15: =_xlfn.XLOOKUP(K15,[1]库销表!$F:$F,[1]库销表!$IE:$IE) -> 0 | CX15: =_xlfn.XLOOKUP(K15,[1]库销表!$F:$F,[1]库销表!$IF:$IF) -> 0 | CY15: =_xlfn.XLOOKUP(K15,[1]库销表!$F:$F,[1]库销表!$FL:$FL) -> 0 | CZ15: =_xlfn.XLOOKUP(K15,数据更新表!E:E,数据更新表!F:F,0) -> 0 | DA15: 0 | DB15: =_xlfn.XLOOKUP(K15,数据更新表!E:E,数据更新表!G:G) -> #N/A | DC15: =_xlfn.XLOOKUP(L15,数据更新表!Z:Z,数据更新表!AH:AH) -> 0 | DD15: =_xlfn.XLOOKUP(L15,数据更新表!Z:Z,数据更新表!AE:AE) -> 0 | DE15: =_xlfn.XLOOKUP(L15,数据更新表!Z:Z,数据更新表!AF:AF) -> 0 | DF15: =_xlfn.XLOOKUP(K15,数据更新表!Z:Z,数据更新表!AG:AG) -> #N/A | DG15: =_xlfn.XLOOKUP(L15,数据更新表!Z:Z,数据更新表!AD:AD) -> 0 | DH15: =_xlfn.XLOOKUP(L15,数据更新表!Z:Z,数据更新表!AA:AA) -> 1448 | DI15: =_xlfn.XLOOKUP(L15,数据更新表!Z:Z,数据更新表!AB:AB) -> 0 | DJ15: =_xlfn.XLOOKUP(L15,数据更新表!Z:Z,数据更新表!AC:AC) -> 0.00% | DK15: =_xlfn.XLOOKUP(L15,数据更新表!Z:Z,数据更新表!AI:AI) -> 0.00% | DL15: =_xlfn.XLOOKUP(L15,数据更新表!AL:AL,数据更新表!AM:AM) -> 0.00% | DM15: =_xlfn.XLOOKUP(L15,数据更新表!Z:Z,数据更新表!AJ:AJ) -> 0 | DN15: 9.98 | DO15: 开 | DP15: fengshan-1 | DQ15: 46084 | DU15: 没毛利，最低价215，上榜379 | ED15: 调559 开广 | EE15: 199 | EF15: =EE15/0.7 -> 284.28571 | EG15: 85 | EH15: =EJ15/(EI15+EL15) -> -0.57915569 | EI15: =EG15*$EI$1 -> 221.85 | EJ15: =EE15-EI15-EL15-EO15-EN15-EP15-EQ15 -> -132.567 | EK15: =EJ15/EE15 -> -0.66616583 | EL15: =EX15*3000*$EI$1 -> 7.047 | EM15: =IF(EE15>299,"是","否") -> 否 | EN15: =EE15*0.05 -> 9.95 | EO15: =EE15*0.175 -> 34.825 | EP15: =IF(EE15<299,IF(EE15<99,25,IF(EE15<=149,30,IF(EE15<=299,37,85))),IF(EE15<=498,_xlfn.XLOOKUP(EW15,运费表!A:A,运费表!C:C,"重量超限",-1),_xlfn.XLOOKUP(EW15,运费表!A:A,运费表!D:D,"重量超限",-1))) -> 37 | EQ15: =EE15*0.105 -> 20.895 | ER15: =_xlfn.XLOOKUP(K15,[4]目录表!$H:$H,[4]目录表!$X:$X) -> 0.46 | ES15: =_xlfn.XLOOKUP(K15,[4]目录表!$H:$H,[4]目录表!$Y:$Y) -> 0 | ET15: =_xlfn.XLOOKUP(K15,[4]目录表!$H:$H,[4]目录表!$Z:$Z) -> 0 | EU15: =_xlfn.XLOOKUP(K15,[4]目录表!$H:$H,[4]目录表!$AA:$AA) -> 0 | EV15: =(50*30*30)/50/5000 -> 0.18 | EW15: =IF(EV15>=ER15,EV15,ER15) -> 0.46 | EX15: =_xlfn.XLOOKUP(K15,[2]目录表!$H:$H,[2]目录表!$AB:$AB) -> 0.0009 | EZ15: =CZ15/7 -> 0 | FK15: =_xlfn.XLOOKUP(K15,[2]目录表!$H:$H,[2]目录表!$AJ:$AJ) -> 散货
B16: https://articulo.mercadolibre.com.mx/MLM-3117809716-alternador-chevrolet-aveo-15-85a-2018-2019-2020-2021-2022-_JM#polycard_client=search_best-seller&tracking_id=308eb0f8-3e9c-40b5-988b-e5fca241b761 | C16: 11 | D16: 23 | E16: 45943 | G16: 交流发电机 | H16: 交流发电机A1137 | J16: Alternador Chevrolet Aveo 1.5 85a 2018 2019 2020 2021 2022 | K16: XQ5-QP023-A1137 | M16: 未上架 | N16: =_xlfn.XLOOKUP(L16,数据更新表!J:J,数据更新表!K:K) -> 0 | O16: =IFERROR(_xlfn.XLOOKUP(K16,数据更新表!A:A,数据更新表!B:B),"0") -> 0 | P16: =_xlfn.XLOOKUP(K16,[1]库销表!$F:$F,[1]库销表!$L:$L) -> 0 | Q16: =X16/W16 -> #DIV/0! | S16: =_xlfn.XLOOKUP(K16,数据更新表!R:R,数据更新表!S:S) -> #N/A | T16: =_xlfn.XLOOKUP(K16,数据更新表!V:V,数据更新表!W:W) -> #N/A | V16: =IFERROR(7*O16/CZ16,"0") -> 0 | W16: =CZ16/7 -> 0 | X16: =O16+P16+SUM(BN16:BR16) -> 0 | AF16: =SUM(AG16:BQ16) -> 0 | BS16: =_xlfn.XLOOKUP(K16,[1]库销表!$F:$F,[1]库销表!$L:$L) -> 0 | BT16: =SUM(BU16:CV16) -> 0 | CW16: =_xlfn.XLOOKUP(K16,[1]库销表!$F:$F,[1]库销表!$IE:$IE) -> 0 | CX16: =_xlfn.XLOOKUP(K16,[1]库销表!$F:$F,[1]库销表!$IF:$IF) -> 0 | CY16: =_xlfn.XLOOKUP(K16,[1]库销表!$F:$F,[1]库销表!$FL:$FL) -> 0 | CZ16: =_xlfn.XLOOKUP(K16,数据更新表!E:E,数据更新表!F:F,0) -> 0 | DA16: 0 | DB16: =_xlfn.XLOOKUP(K16,数据更新表!E:E,数据更新表!G:G) -> #N/A | DC16: =_xlfn.XLOOKUP(L16,数据更新表!Z:Z,数据更新表!AH:AH) -> 0 | DD16: =_xlfn.XLOOKUP(L16,数据更新表!Z:Z,数据更新表!AE:AE) -> 0 | DE16: =_xlfn.XLOOKUP(L16,数据更新表!Z:Z,数据更新表!AF:AF) -> 0 | DF16: =_xlfn.XLOOKUP(K16,数据更新表!Z:Z,数据更新表!AG:AG) -> #N/A | DG16: =_xlfn.XLOOKUP(L16,数据更新表!Z:Z,数据更新表!AD:AD) -> 0 | DH16: =_xlfn.XLOOKUP(L16,数据更新表!Z:Z,数据更新表!AA:AA) -> 0 | DI16: =_xlfn.XLOOKUP(L16,数据更新表!Z:Z,数据更新表!AB:AB) -> 0 | DJ16: =_xlfn.XLOOKUP(L16,数据更新表!Z:Z,数据更新表!AC:AC) -> 0 | DK16: =_xlfn.XLOOKUP(L16,数据更新表!Z:Z,数据更新表!AI:AI) -> 0 | DL16: =_xlfn.XLOOKUP(L16,数据更新表!AL:AL,数据更新表!AM:AM) -> 0 | DM16: =_xlfn.XLOOKUP(L16,数据更新表!Z:Z,数据更新表!AJ:AJ) -> 0 | EE16: =_xlfn.XLOOKUP(L16,数据更新表!J:J,数据更新表!L:L) -> 0 | EF16: =_xlfn.XLOOKUP(L16,数据更新表!J:J,数据更新表!M:M) -> 0 | EG16: 265 | EH16: =EJ16/(EI16+EL16) -> -1.0321104 | EI16: =EG16*$EI$1 -> 691.65 | EJ16: =EE16-EI16-EL16-EO16-EN16-EP16-EQ16 -> -803.563 | EK16: =EJ16/EE16 -> #DIV/0! | EL16: =EX16*3000*$EI$1 -> 86.913 | EM16: =IF(EE16>299,"是","否") -> 否 | EN16: =EE16*0.05 -> 0 | EO16: =EE16*0.175 -> 0 | EP16: =IF(EE16<299,IF(EE16<99,25,IF(EE16<=149,30,IF(EE16<=299,37,85))),IF(EE16<=498,_xlfn.XLOOKUP(EW16,运费表!A:A,运费表!C:C,"重量超限",-1),_xlfn.XLOOKUP(EW16,运费表!A:A,运费表!D:D,"重量超限",-1))) -> 25 | EQ16: =EE16*0.105 -> 0 | ER16: =_xlfn.XLOOKUP(K16,[4]目录表!$H:$H,[4]目录表!$X:$X) -> 6.55 | ES16: =_xlfn.XLOOKUP(K16,[4]目录表!$H:$H,[4]目录表!$Y:$Y) -> 25 | ET16: =_xlfn.XLOOKUP(K16,[4]目录表!$H:$H,[4]目录表!$Z:$Z) -> 24 | EU16: =_xlfn.XLOOKUP(K16,[4]目录表!$H:$H,[4]目录表!$AA:$AA) -> 18.5 | EV16: =ES16*ET16*EU16/5000 -> 2.22 | EW16: =IF(EV16>=ER16,EV16,ER16) -> 6.55 | EX16: =_xlfn.XLOOKUP(K16,[2]目录表!$H:$H,[2]目录表!$AB:$AB) -> 0.0111 | EZ16: =CZ16/7 -> 0 | FK16: =_xlfn.XLOOKUP(K16,[2]目录表!$H:$H,[2]目录表!$AJ:$AJ) -> 散货
B17: https://www.mercadolibre.com.mx/alternador-para-fiat-uno-mobi-500-092023-ram-rapid-1723/up/MLMU458091911#polycard_client=search_best-seller&tracking_id=c00fdf92-bf20-49d5-890d-57c15933cb7e&wid=MLM3311433164&sid=search | C17: 13 | D17: 30 | E17: 45943 | G17: 交流发电机 | H17: 交流发电机101210-1650 | J17: Alternador Para Fiat Uno, Mobi, 500 09-2023, Ram Rapid 17-23 | K17: XQ5-QP024-101210-1650 | M17: 未上架 | N17: =_xlfn.XLOOKUP(L17,数据更新表!J:J,数据更新表!K:K) -> 0 | O17: =IFERROR(_xlfn.XLOOKUP(K17,数据更新表!A:A,数据更新表!B:B),"0") -> 0 | P17: =_xlfn.XLOOKUP(K17,[1]库销表!$F:$F,[1]库销表!$L:$L) -> 0 | Q17: =X17/W17 -> #DIV/0! | S17: =_xlfn.XLOOKUP(K17,数据更新表!R:R,数据更新表!S:S) -> #N/A | T17: =_xlfn.XLOOKUP(K17,数据更新表!V:V,数据更新表!W:W) -> #N/A | V17: =IFERROR(7*O17/CZ17,"0") -> 0 | W17: =CZ17/7 -> 0 | X17: =O17+P17+SUM(BN17:BR17) -> 0 | AF17: =SUM(AG17:BQ17) -> 0 | BS17: =_xlfn.XLOOKUP(K17,[1]库销表!$F:$F,[1]库销表!$L:$L) -> 0 | BT17: =SUM(BU17:CV17) -> 0 | CW17: =_xlfn.XLOOKUP(K17,[1]库销表!$F:$F,[1]库销表!$IE:$IE) -> 0 | CX17: =_xlfn.XLOOKUP(K17,[1]库销表!$F:$F,[1]库销表!$IF:$IF) -> 0 | CY17: =_xlfn.XLOOKUP(K17,[1]库销表!$F:$F,[1]库销表!$FL:$FL) -> 0 | CZ17: =_xlfn.XLOOKUP(K17,数据更新表!E:E,数据更新表!F:F,0) -> 0 | DA17: 0 | DB17: =_xlfn.XLOOKUP(K17,数据更新表!E:E,数据更新表!G:G) -> #N/A | DC17: =_xlfn.XLOOKUP(L17,数据更新表!Z:Z,数据更新表!AH:AH) -> 0 | DD17: =_xlfn.XLOOKUP(L17,数据更新表!Z:Z,数据更新表!AE:AE) -> 0 | DE17: =_xlfn.XLOOKUP(L17,数据更新表!Z:Z,数据更新表!AF:AF) -> 0 | DF17: =_xlfn.XLOOKUP(K17,数据更新表!Z:Z,数据更新表!AG:AG) -> #N/A | DG17: =_xlfn.XLOOKUP(L17,数据更新表!Z:Z,数据更新表!AD:AD) -> 0 | DH17: =_xlfn.XLOOKUP(L17,数据更新表!Z:Z,数据更新表!AA:AA) -> 0 | DI17: =_xlfn.XLOOKUP(L17,数据更新表!Z:Z,数据更新表!AB:AB) -> 0 | DJ17: =_xlfn.XLOOKUP(L17,数据更新表!Z:Z,数据更新表!AC:AC) -> 0 | DK17: =_xlfn.XLOOKUP(L17,数据更新表!Z:Z,数据更新表!AI:AI) -> 0 | DL17: =_xlfn.XLOOKUP(L17,数据更新表!AL:AL,数据更新表!AM:AM) -> 0 | DM17: =_xlfn.XLOOKUP(L17,数据更新表!Z:Z,数据更新表!AJ:AJ) -> 0 | EE17: =_xlfn.XLOOKUP(L17,数据更新表!J:J,数据更新表!L:L) -> 0 | EF17: =_xlfn.XLOOKUP(L17,数据更新表!J:J,数据更新表!M:M) -> 0 | EG17: 265 | EH17: =EJ17/(EI17+EL17) -> -1.0321104 | EI17: =EG17*$EI$1 -> 691.65 | EJ17: =EE17-EI17-EL17-EO17-EN17-EP17-EQ17 -> -803.563 | EK17: =EJ17/EE17 -> #DIV/0! | EL17: =EX17*3000*$EI$1 -> 86.913 | EM17: =IF(EE17>299,"是","否") -> 否 | EN17: =EE17*0.05 -> 0 | EO17: =EE17*0.175 -> 0 | EP17: =IF(EE17<299,IF(EE17<99,25,IF(EE17<=149,30,IF(EE17<=299,37,85))),IF(EE17<=498,_xlfn.XLOOKUP(EW17,运费表!A:A,运费表!C:C,"重量超限",-1),_xlfn.XLOOKUP(EW17,运费表!A:A,运费表!D:D,"重量超限",-1))) -> 25 | EQ17: =EE17*0.105 -> 0 | ER17: =_xlfn.XLOOKUP(K17,[4]目录表!$H:$H,[4]目录表!$X:$X) -> 7.5 | ES17: =_xlfn.XLOOKUP(K17,[4]目录表!$H:$H,[4]目录表!$Y:$Y) -> 25 | ET17: =_xlfn.XLOOKUP(K17,[4]目录表!$H:$H,[4]目录表!$Z:$Z) -> 24 | EU17: =_xlfn.XLOOKUP(K17,[4]目录表!$H:$H,[4]目录表!$AA:$AA) -> 18.5 | EV17: =ES17*ET17*EU17/5000 -> 2.22 | EW17: =IF(EV17>=ER17,EV17,ER17) -> 7.5 | EX17: =_xlfn.XLOOKUP(K17,[2]目录表!$H:$H,[2]目录表!$AB:$AB) -> 0.0111 | EZ17: =CZ17/7 -> 0 | FK17: =_xlfn.XLOOKUP(K17,[2]目录表!$H:$H,[2]目录表!$AJ:$AJ) -> 散货
B18: Muelle Reloj Para Nissan Np300 Navara D23 2.5lts 2016-2020 | Meses sin interés | C18: 15 | D18: 38 | E18: 46044 | G18: 气囊游丝 | H18: 气囊游丝25554-3TS0A | J18: Muelle Reloj Para Nissan Np300 Navara D23 2.5lts 2016-2020 | K18: XQ5-QP020-25554-3TS0A | L18: 2705951099 | M18: 新上架 | N18: =_xlfn.XLOOKUP(L18,数据更新表!J:J,数据更新表!K:K) -> -- | O18: =IFERROR(_xlfn.XLOOKUP(K18,数据更新表!A:A,数据更新表!B:B),"0") -> 49 | P18: =_xlfn.XLOOKUP(K18,[1]库销表!$F:$F,[1]库销表!$L:$L) -> 0 | Q18: =X18/W18 -> 343 | S18: =_xlfn.XLOOKUP(K18,数据更新表!R:R,数据更新表!S:S) -> #N/A | T18: =_xlfn.XLOOKUP(K18,数据更新表!V:V,数据更新表!W:W) -> #N/A | V18: =IFERROR(7*O18/CZ18,"0") -> 343 | W18: =CZ18/7 -> 0.14285714 | X18: =O18+P18+SUM(BN18:BR18) -> 49 | AF18: =SUM(AG18:BQ18) -> 50 | AI18: 50 | BS18: =_xlfn.XLOOKUP(K18,[1]库销表!$F:$F,[1]库销表!$L:$L) -> 0 | BT18: =SUM(BU18:CV18) -> 0 | CW18: =_xlfn.XLOOKUP(K18,[1]库销表!$F:$F,[1]库销表!$IE:$IE) -> 0 | CX18: =_xlfn.XLOOKUP(K18,[1]库销表!$F:$F,[1]库销表!$IF:$IF) -> 0 | CY18: =_xlfn.XLOOKUP(K18,[1]库销表!$F:$F,[1]库销表!$FL:$FL) -> 0 | CZ18: =_xlfn.XLOOKUP(K18,数据更新表!E:E,数据更新表!F:F,0) -> 1 | DA18: 0 | DB18: =_xlfn.XLOOKUP(K18,数据更新表!E:E,数据更新表!G:G) -> 1 | DC18: =_xlfn.XLOOKUP(L18,数据更新表!Z:Z,数据更新表!AH:AH) -> 1 | DD18: =_xlfn.XLOOKUP(L18,数据更新表!Z:Z,数据更新表!AE:AE) -> 0 | DE18: =_xlfn.XLOOKUP(L18,数据更新表!Z:Z,数据更新表!AF:AF) -> 0 | DF18: =_xlfn.XLOOKUP(K18,数据更新表!Z:Z,数据更新表!AG:AG) -> #N/A | DG18: =_xlfn.XLOOKUP(L18,数据更新表!Z:Z,数据更新表!AD:AD) -> 0 | DH18: =_xlfn.XLOOKUP(L18,数据更新表!Z:Z,数据更新表!AA:AA) -> 511 | DI18: =_xlfn.XLOOKUP(L18,数据更新表!Z:Z,数据更新表!AB:AB) -> 0 | DJ18: =_xlfn.XLOOKUP(L18,数据更新表!Z:Z,数据更新表!AC:AC) -> 0.00% | DK18: =_xlfn.XLOOKUP(L18,数据更新表!Z:Z,数据更新表!AI:AI) -> 0.00% | DL18: =_xlfn.XLOOKUP(L18,数据更新表!AL:AL,数据更新表!AM:AM) -> 0.05% | DM18: =_xlfn.XLOOKUP(L18,数据更新表!Z:Z,数据更新表!AJ:AJ) -> 0 | DN18: 6.6 | DO18: 开 | DP18: qi nang_5 | DQ18: 46084 | ED18: 调394 开广 | EE18: 298 | EF18: =EE18/0.7 -> 425.71429 | EG18: 26 | EH18: =EJ18/(EI18+EL18) -> 1.0784772 | EI18: =EG18*$EI$1 -> 67.86 | EJ18: =EE18-EI18-EL18-EO18-EN18-EP18-EQ18 -> 84.400781 | EK18: =EJ18/EE18 -> 0.2832241 | EL18: =EX18*3000*$EI$1 -> 10.399219 | EM18: =IF(EE18>299,"是","否") -> 否 | EN18: =EE18*0.05 -> 14.9 | EO18: =EE18*0.175 -> 52.15 | EP18: =IF(EE18<299,IF(EE18<99,25,IF(EE18<=149,30,IF(EE18<=299,37,85))),IF(EE18<=498,_xlfn.XLOOKUP(EW18,运费表!A:A,运费表!C:C,"重量超限",-1),_xlfn.XLOOKUP(EW18,运费表!A:A,运费表!D:D,"重量超限",-1))) -> 37 | EQ18: =EE18*0.105 -> 31.29 | ER18: =_xlfn.XLOOKUP(K18,[4]目录表!$H:$H,[4]目录表!$X:$X) -> 0.18 | ES18: =_xlfn.XLOOKUP(K18,[4]目录表!$H:$H,[4]目录表!$Y:$Y) -> 12.5 | ET18: =_xlfn.XLOOKUP(K18,[4]目录表!$H:$H,[4]目录表!$Z:$Z) -> 12.5 | EU18: =_xlfn.XLOOKUP(K18,[4]目录表!$H:$H,[4]目录表!$AA:$AA) -> 8.5 | EV18: =ES18*ET18*EU18/5000 -> 0.265625 | EW18: =IF(EV18>=ER18,EV18,ER18) -> 0.265625 | EX18: =_xlfn.XLOOKUP(K18,[2]目录表!$H:$H,[2]目录表!$AB:$AB) -> 0.001328125 | EZ18: =CZ18/7 -> 0.14285714 | FK18: =_xlfn.XLOOKUP(K18,[2]目录表!$H:$H,[2]目录表!$AJ:$AJ) -> 散货
B19: Resorte Reloj 84306-22010 Para 2006-2014 Toyota Yaris | Envío gratis | C19: 5 | D19: 22 | E19: 46044 | G19: 气囊游丝 | H19: 气囊游丝84306-22010 | J19: Resorte Reloj 84306-22010 Para 2006-2014 Toyota Yaris | K19: XQ5-QP021-84306-22010 | L19: 2705860671 | M19: 新上架 | N19: =_xlfn.XLOOKUP(L19,数据更新表!J:J,数据更新表!K:K) -> #N/A | O19: =IFERROR(_xlfn.XLOOKUP(K19,数据更新表!A:A,数据更新表!B:B),"0") -> 50 | P19: =_xlfn.XLOOKUP(K19,[1]库销表!$F:$F,[1]库销表!$L:$L) -> 0 | Q19: =X19/W19 -> #DIV/0! | S19: =_xlfn.XLOOKUP(K19,数据更新表!R:R,数据更新表!S:S) -> #N/A | T19: =_xlfn.XLOOKUP(K19,数据更新表!V:V,数据更新表!W:W) -> #N/A | V19: =IFERROR(7*O19/CZ19,"0") -> 0 | W19: =CZ19/7 -> 0 | X19: =O19+P19+SUM(BN19:BR19) -> 50 | AF19: =SUM(AG19:BQ19) -> 50 | AI19: 50 | BS19: =_xlfn.XLOOKUP(K19,[1]库销表!$F:$F,[1]库销表!$L:$L) -> 0 | BT19: =SUM(BU19:CV19) -> 0 | CW19: =_xlfn.XLOOKUP(K19,[1]库销表!$F:$F,[1]库销表!$IE:$IE) -> 0 | CX19: =_xlfn.XLOOKUP(K19,[1]库销表!$F:$F,[1]库销表!$IF:$IF) -> 0 | CY19: =_xlfn.XLOOKUP(K19,[1]库销表!$F:$F,[1]库销表!$FL:$FL) -> 0 | CZ19: =_xlfn.XLOOKUP(K19,数据更新表!E:E,数据更新表!F:F,0) -> 0 | DA19: 0 | DB19: =_xlfn.XLOOKUP(K19,数据更新表!E:E,数据更新表!G:G) -> #N/A | DC19: =_xlfn.XLOOKUP(L19,数据更新表!Z:Z,数据更新表!AH:AH) -> #N/A | DD19: =_xlfn.XLOOKUP(L19,数据更新表!Z:Z,数据更新表!AE:AE) -> #N/A | DE19: =_xlfn.XLOOKUP(L19,数据更新表!Z:Z,数据更新表!AF:AF) -> #N/A | DF19: =_xlfn.XLOOKUP(K19,数据更新表!Z:Z,数据更新表!AG:AG) -> #N/A | DG19: =_xlfn.XLOOKUP(L19,数据更新表!Z:Z,数据更新表!AD:AD) -> #N/A | DH19: =_xlfn.XLOOKUP(L19,数据更新表!Z:Z,数据更新表!AA:AA) -> #N/A | DI19: =_xlfn.XLOOKUP(L19,数据更新表!Z:Z,数据更新表!AB:AB) -> #N/A | DJ19: =_xlfn.XLOOKUP(L19,数据更新表!Z:Z,数据更新表!AC:AC) -> #N/A | DK19: =_xlfn.XLOOKUP(L19,数据更新表!Z:Z,数据更新表!AI:AI) -> #N/A | DL19: =_xlfn.XLOOKUP(L19,数据更新表!AL:AL,数据更新表!AM:AM) -> 0.00% | DM19: =_xlfn.XLOOKUP(L19,数据更新表!Z:Z,数据更新表!AJ:AJ) -> #N/A | DN19: 6.6 | DO19: 开 | DP19: qi nang_5 | DQ19: 46084 | ED19: 调415 开广 | EE19: 149 | EF19: =EE19/0.7 -> 212.85714 | EG19: 16 | EH19: =EJ19/(EI19+EL19) -> 0.33878539 | EI19: =EG19*$EI$1 -> 41.76 | EJ19: =EE19-EI19-EL19-EO19-EN19-EP19-EQ19 -> 17.670781 | EK19: =EJ19/EE19 -> 0.11859585 | EL19: =EX19*3000*$EI$1 -> 10.399219 | EM19: =IF(EE19>299,"是","否") -> 否 | EN19: =EE19*0.05 -> 7.45 | EO19: =EE19*0.175 -> 26.075 | EP19: =IF(EE19<299,IF(EE19<99,25,IF(EE19<=149,30,IF(EE19<=299,37,85))),IF(EE19<=498,_xlfn.XLOOKUP(EW19,运费表!A:A,运费表!C:C,"重量超限",-1),_xlfn.XLOOKUP(EW19,运费表!A:A,运费表!D:D,"重量超限",-1))) -> 30 | EQ19: =EE19*0.105 -> 15.645 | ER19: =_xlfn.XLOOKUP(K19,[4]目录表!$H:$H,[4]目录表!$X:$X) -> 0.18 | ES19: =_xlfn.XLOOKUP(K19,[4]目录表!$H:$H,[4]目录表!$Y:$Y) -> 12.5 | ET19: =_xlfn.XLOOKUP(K19,[4]目录表!$H:$H,[4]目录表!$Z:$Z) -> 12.5 | EU19: =_xlfn.XLOOKUP(K19,[4]目录表!$H:$H,[4]目录表!$AA:$AA) -> 8.5 | EV19: =ES19*ET19*EU19/5000 -> 0.265625 | EW19: =IF(EV19>=ER19,EV19,ER19) -> 0.265625 | EX19: =_xlfn.XLOOKUP(K19,[2]目录表!$H:$H,[2]目录表!$AB:$AB) -> 0.001328125 | EZ19: =CZ19/7 -> 0 | FK19: =_xlfn.XLOOKUP(K19,[2]目录表!$H:$H,[2]目录表!$AJ:$AJ) -> 散货
B20: Espiral Reloj Pista Carrete Mazda 3 2004 2005 2006 2007 2008 | Envío gratis | C20: 0 | D20: 3 | E20: 46045 | G20: 气囊游丝 | H20: 气囊游丝BP4K-66-CS0 | J20: Espiral Reloj Pista Carrete Mazda 3 2004 2005 2006 2007 2008 | K20: XQ5-QP022-BP4K-66-CS0 | L20: 4700259114 | M20: 新上架 | N20: =_xlfn.XLOOKUP(L20,数据更新表!J:J,数据更新表!K:K) -> 100 | O20: =IFERROR(_xlfn.XLOOKUP(K20,数据更新表!A:A,数据更新表!B:B),"0") -> 49 | P20: =_xlfn.XLOOKUP(K20,[1]库销表!$F:$F,[1]库销表!$L:$L) -> 0 | Q20: =X20/W20 -> 343 | S20: =_xlfn.XLOOKUP(K20,数据更新表!R:R,数据更新表!S:S) -> #N/A | T20: =_xlfn.XLOOKUP(K20,数据更新表!V:V,数据更新表!W:W) -> #N/A | V20: =IFERROR(7*O20/CZ20,"0") -> 343 | W20: =CZ20/7 -> 0.14285714 | X20: =O20+P20+SUM(BN20:BR20) -> 49 | AF20: =SUM(AG20:BQ20) -> 50 | AI20: 50 | BS20: =_xlfn.XLOOKUP(K20,[1]库销表!$F:$F,[1]库销表!$L:$L) -> 0 | BT20: =SUM(BU20:CV20) -> 0 | CW20: =_xlfn.XLOOKUP(K20,[1]库销表!$F:$F,[1]库销表!$IE:$IE) -> 0 | CX20: =_xlfn.XLOOKUP(K20,[1]库销表!$F:$F,[1]库销表!$IF:$IF) -> 0 | CY20: =_xlfn.XLOOKUP(K20,[1]库销表!$F:$F,[1]库销表!$FL:$FL) -> 0 | CZ20: =_xlfn.XLOOKUP(K20,数据更新表!E:E,数据更新表!F:F,0) -> 1 | DA20: 0 | DB20: =_xlfn.XLOOKUP(K20,数据更新表!E:E,数据更新表!G:G) -> 0 | DC20: =_xlfn.XLOOKUP(L20,数据更新表!Z:Z,数据更新表!AH:AH) -> 0 | DD20: =_xlfn.XLOOKUP(L20,数据更新表!Z:Z,数据更新表!AE:AE) -> 1 | DE20: =_xlfn.XLOOKUP(L20,数据更新表!Z:Z,数据更新表!AF:AF) -> 1 | DF20: =_xlfn.XLOOKUP(K20,数据更新表!Z:Z,数据更新表!AG:AG) -> #N/A | DG20: =_xlfn.XLOOKUP(L20,数据更新表!Z:Z,数据更新表!AD:AD) -> 185.29 | DH20: =_xlfn.XLOOKUP(L20,数据更新表!Z:Z,数据更新表!AA:AA) -> 7336 | DI20: =_xlfn.XLOOKUP(L20,数据更新表!Z:Z,数据更新表!AB:AB) -> 17 | DJ20: =_xlfn.XLOOKUP(L20,数据更新表!Z:Z,数据更新表!AC:AC) -> 42.21% | DK20: =_xlfn.XLOOKUP(L20,数据更新表!Z:Z,数据更新表!AI:AI) -> 42.21% | DL20: =_xlfn.XLOOKUP(L20,数据更新表!AL:AL,数据更新表!AM:AM) -> 45.69% | DM20: =_xlfn.XLOOKUP(L20,数据更新表!Z:Z,数据更新表!AJ:AJ) -> 2.37 | DN20: 6.6 | DO20: 开 | DP20: qi nang_5 | DQ20: 46084 | ED20: 调527 开广 | EE20: 439 | EF20: =EE20/0.7 -> 627.14286 | EG20: 26 | EH20: =EJ20/(EI20+EL20) -> 2.0888374 | EI20: =EG20*$EI$1 -> 67.86 | EJ20: =EE20-EI20-EL20-EO20-EN20-EP20-EQ20 -> 163.47078 | EK20: =EJ20/EE20 -> 0.3723708 | EL20: =EX20*3000*$EI$1 -> 10.399219 | EM20: =IF(EE20>299,"是","否") -> 是 | EN20: =EE20*0.05 -> 21.95 | EO20: =EE20*0.175 -> 76.825 | EP20: =IF(EE20<299,IF(EE20<99,25,IF(EE20<=149,30,IF(EE20<=299,37,85))),IF(EE20<=498,_xlfn.XLOOKUP(EW20,运费表!A:A,运费表!C:C,"重量超限",-1),_xlfn.XLOOKUP(EW20,运费表!A:A,运费表!D:D,"重量超限",-1))) -> 52.4 | EQ20: =EE20*0.105 -> 46.095 | ER20: =_xlfn.XLOOKUP(K20,[4]目录表!$H:$H,[4]目录表!$X:$X) -> 0.18 | ES20: =_xlfn.XLOOKUP(K20,[4]目录表!$H:$H,[4]目录表!$Y:$Y) -> 12.5 | ET20: =_xlfn.XLOOKUP(K20,[4]目录表!$H:$H,[4]目录表!$Z:$Z) -> 12.5 | EU20: =_xlfn.XLOOKUP(K20,[4]目录表!$H:$H,[4]目录表!$AA:$AA) -> 8.5 | EV20: =ES20*ET20*EU20/5000 -> 0.265625 | EW20: =IF(EV20>=ER20,EV20,ER20) -> 0.265625 | EX20: =_xlfn.XLOOKUP(K20,[2]目录表!$H:$H,[2]目录表!$AB:$AB) -> 0.001328125 | EZ20: =CZ20/7 -> 0.14285714 | FK20: =_xlfn.XLOOKUP(K20,[2]目录表!$H:$H,[2]目录表!$AJ:$AJ) -> 散货
B21: Pista Espiral Volante Claxon Bolsa Versa 12-19 March 12-20 | Meses sin interés | C21: 15 | D21: 31 | E21: 46038 | G21: 气囊游丝 | H21: 气囊游丝25554-3DN0A | J21: Pista Espiral Volante Claxon Bolsa Versa 12-19 March 12-20 | K21: XQ5-QP006-25554-3DN0A | L21: 4684129758 | M21: 新上架 | N21: =_xlfn.XLOOKUP(L21,数据更新表!J:J,数据更新表!K:K) -> 100 | O21: =IFERROR(_xlfn.XLOOKUP(K21,数据更新表!A:A,数据更新表!B:B),"0") -> 33 | P21: =_xlfn.XLOOKUP(K21,[1]库销表!$F:$F,[1]库销表!$L:$L) -> 0 | Q21: =X21/W21 -> 57.75 | S21: =_xlfn.XLOOKUP(K21,数据更新表!R:R,数据更新表!S:S) -> #N/A | T21: =_xlfn.XLOOKUP(K21,数据更新表!V:V,数据更新表!W:W) -> #N/A | V21: =IFERROR(7*O21/CZ21,"0") -> 57.75 | W21: =CZ21/7 -> 0.57142857 | X21: =O21+P21+SUM(BN21:BR21) -> 33 | AF21: =SUM(AG21:BQ21) -> 50 | AL21: 50 | BS21: =_xlfn.XLOOKUP(K21,[1]库销表!$F:$F,[1]库销表!$L:$L) -> 0 | BT21: =SUM(BU21:CV21) -> 0 | CW21: =_xlfn.XLOOKUP(K21,[1]库销表!$F:$F,[1]库销表!$IE:$IE) -> 0 | CX21: =_xlfn.XLOOKUP(K21,[1]库销表!$F:$F,[1]库销表!$IF:$IF) -> 0 | CY21: =_xlfn.XLOOKUP(K21,[1]库销表!$F:$F,[1]库销表!$FL:$FL) -> 0 | CZ21: =_xlfn.XLOOKUP(K21,数据更新表!E:E,数据更新表!F:F,0) -> 4 | DA21: 5 | DB21: =_xlfn.XLOOKUP(K21,数据更新表!E:E,数据更新表!G:G) -> 1 | DC21: =_xlfn.XLOOKUP(L21,数据更新表!Z:Z,数据更新表!AH:AH) -> 4 | DD21: =_xlfn.XLOOKUP(L21,数据更新表!Z:Z,数据更新表!AE:AE) -> 0 | DE21: =_xlfn.XLOOKUP(L21,数据更新表!Z:Z,数据更新表!AF:AF) -> 0 | DF21: =_xlfn.XLOOKUP(K21,数据更新表!Z:Z,数据更新表!AG:AG) -> #N/A | DG21: =_xlfn.XLOOKUP(L21,数据更新表!Z:Z,数据更新表!AD:AD) -> 77.4 | DH21: =_xlfn.XLOOKUP(L21,数据更新表!Z:Z,数据更新表!AA:AA) -> 6619 | DI21: =_xlfn.XLOOKUP(L21,数据更新表!Z:Z,数据更新表!AB:AB) -> 24 | DJ21: =_xlfn.XLOOKUP(L21,数据更新表!Z:Z,数据更新表!AC:AC) -> 0.00% | DK21: =_xlfn.XLOOKUP(L21,数据更新表!Z:Z,数据更新表!AI:AI) -> 7.47% | DL21: =_xlfn.XLOOKUP(L21,数据更新表!AL:AL,数据更新表!AM:AM) -> 5.49% | DM21: =_xlfn.XLOOKUP(L21,数据更新表!Z:Z,数据更新表!AJ:AJ) -> 0 | DN21: 8 | DO21: 开 | DP21: qi nang-8 | DQ21: 46074 | DU21: 同366 | EE21: 259 | EF21: =EE21/0.7 -> 370 | EG21: 27 | EH21: =EJ21/(EI21+EL21) -> 0.54035173 | EI21: =EG21*$EI$1 -> 70.47 | EJ21: =EE21-EI21-EL21-EO21-EN21-EP21-EQ21 -> 47.8944 | EK21: =EJ21/EE21 -> 0.18492046 | EL21: =EX21*3000*$EI$1 -> 18.1656 | EM21: =IF(EE21>299,"是","否") -> 否 | EN21: =EE21*0.05 -> 12.95 | EO21: =EE21*0.175 -> 45.325 | EP21: =IF(EE21<299,IF(EE21<99,25,IF(EE21<=149,30,IF(EE21<=299,37,85))),IF(EE21<=498,_xlfn.XLOOKUP(EW21,运费表!A:A,运费表!C:C,"重量超限",-1),_xlfn.XLOOKUP(EW21,运费表!A:A,运费表!D:D,"重量超限",-1))) -> 37 | EQ21: =EE21*0.105 -> 27.195 | ER21: =_xlfn.XLOOKUP(K21,[4]目录表!$H:$H,[4]目录表!$X:$X) -> 0.38 | ES21: =_xlfn.XLOOKUP(K21,[4]目录表!$H:$H,[4]目录表!$Y:$Y) -> 16 | ET21: =_xlfn.XLOOKUP(K21,[4]目录表!$H:$H,[4]目录表!$Z:$Z) -> 14.5 | EU21: =_xlfn.XLOOKUP(K21,[4]目录表!$H:$H,[4]目录表!$AA:$AA) -> 10 | EV21: =ES21*ET21*EU21/5000 -> 0.464 | EW21: =IF(EV21>=ER21,EV21,ER21) -> 0.464 | EX21: =_xlfn.XLOOKUP(K21,[2]目录表!$H:$H,[2]目录表!$AB:$AB) -> 0.00232 | EZ21: =CZ21/7 -> 0.57142857 | FK21: =_xlfn.XLOOKUP(K21,[2]目录表!$H:$H,[2]目录表!$AJ:$AJ) -> 散货
B22: Resorte Reloj Sensor Para Jeep Patriot 2007 A 2016 | Meses sin interés | C22: 5 | D22: 11 | E22: 46040 | G22: 气囊游丝 | H22: 气囊游丝5156106AF-带角度 | J22: Resorte Reloj Sensor Para Jeep Patriot 2007 A 2016 | K22: XQ5-QP007-5156106AF | L22: 2697065107 | M22: 新上架 | N22: =_xlfn.XLOOKUP(L22,数据更新表!J:J,数据更新表!K:K) -> #N/A | O22: =IFERROR(_xlfn.XLOOKUP(K22,数据更新表!A:A,数据更新表!B:B),"0") -> 0 | P22: =_xlfn.XLOOKUP(K22,[1]库销表!$F:$F,[1]库销表!$L:$L) -> 0 | Q22: =X22/W22 -> #DIV/0! | S22: =_xlfn.XLOOKUP(K22,数据更新表!R:R,数据更新表!S:S) -> #N/A | T22: =_xlfn.XLOOKUP(K22,数据更新表!V:V,数据更新表!W:W) -> #N/A | V22: =IFERROR(7*O22/CZ22,"0") -> 0 | W22: =CZ22/7 -> 0 | X22: =O22+P22+SUM(BN22:BR22) -> 0 | AF22: =SUM(AG22:BQ22) -> 20 | AL22: 20 | BS22: =_xlfn.XLOOKUP(K22,[1]库销表!$F:$F,[1]库销表!$L:$L) -> 0 | BT22: =SUM(BU22:CV22) -> 0 | CW22: =_xlfn.XLOOKUP(K22,[1]库销表!$F:$F,[1]库销表!$IE:$IE) -> 0 | CX22: =_xlfn.XLOOKUP(K22,[1]库销表!$F:$F,[1]库销表!$IF:$IF) -> 0 | CY22: =_xlfn.XLOOKUP(K22,[1]库销表!$F:$F,[1]库销表!$FL:$FL) -> 0 | CZ22: =_xlfn.XLOOKUP(K22,数据更新表!E:E,数据更新表!F:F,0) -> 0 | DA22: 8 | DB22: =_xlfn.XLOOKUP(K22,数据更新表!E:E,数据更新表!G:G) -> #N/A | DC22: =_xlfn.XLOOKUP(L22,数据更新表!Z:Z,数据更新表!AH:AH) -> #N/A | DD22: =_xlfn.XLOOKUP(L22,数据更新表!Z:Z,数据更新表!AE:AE) -> #N/A | DE22: =_xlfn.XLOOKUP(L22,数据更新表!Z:Z,数据更新表!AF:AF) -> #N/A | DF22: =_xlfn.XLOOKUP(K22,数据更新表!Z:Z,数据更新表!AG:AG) -> #N/A | DG22: =_xlfn.XLOOKUP(L22,数据更新表!Z:Z,数据更新表!AD:AD) -> #N/A | DH22: =_xlfn.XLOOKUP(L22,数据更新表!Z:Z,数据更新表!AA:AA) -> #N/A | DI22: =_xlfn.XLOOKUP(L22,数据更新表!Z:Z,数据更新表!AB:AB) -> #N/A | DJ22: =_xlfn.XLOOKUP(L22,数据更新表!Z:Z,数据更新表!AC:AC) -> #N/A | DK22: =_xlfn.XLOOKUP(L22,数据更新表!Z:Z,数据更新表!AI:AI) -> #N/A | DL22: =_xlfn.XLOOKUP(L22,数据更新表!AL:AL,数据更新表!AM:AM) -> 5.52% | DM22: =_xlfn.XLOOKUP(L22,数据更新表!Z:Z,数据更新表!AJ:AJ) -> #N/A | DN22: 10 | DO22: 开 | DP22: qi nang_1 | DQ22: 46074 | DU22: 同行1025 | EE22: 999 | EF22: =EE22/0.7 -> 1427.1429 | EG22: 165 | EH22: =EJ22/(EI22+EL22) -> 0.33535911 | EI22: =EG22*$EI$1 -> 430.65 | EJ22: =EE22-EI22-EL22-EO22-EN22-EP22-EQ22 -> 150.5144 | EK22: =EJ22/EE22 -> 0.15066507 | EL22: =EX22*3000*$EI$1 -> 18.1656 | EM22: =IF(EE22>299,"是","否") -> 是 | EN22: =EE22*0.05 -> 49.95 | EO22: =EE22*0.175 -> 174.825 | EP22: =IF(EE22<299,IF(EE22<99,25,IF(EE22<=149,30,IF(EE22<=299,37,85))),IF(EE22<=498,_xlfn.XLOOKUP(EW22,运费表!A:A,运费表!C:C,"重量超限",-1),_xlfn.XLOOKUP(EW22,运费表!A:A,运费表!D:D,"重量超限",-1))) -> 70 | EQ22: =EE22*0.105 -> 104.895 | ER22: =_xlfn.XLOOKUP(K22,[4]目录表!$H:$H,[4]目录表!$X:$X) -> 0.38 | ES22: =_xlfn.XLOOKUP(K22,[4]目录表!$H:$H,[4]目录表!$Y:$Y) -> 16 | ET22: =_xlfn.XLOOKUP(K22,[4]目录表!$H:$H,[4]目录表!$Z:$Z) -> 14.5 | EU22: =_xlfn.XLOOKUP(K22,[4]目录表!$H:$H,[4]目录表!$AA:$AA) -> 10 | EV22: =ES22*ET22*EU22/5000 -> 0.464 | EW22: =IF(EV22>=ER22,EV22,ER22) -> 0.464 | EX22: =_xlfn.XLOOKUP(K22,[2]目录表!$H:$H,[2]目录表!$AB:$AB) -> 0.00232 | EZ22: =CZ22/7 -> 0 | FK22: =_xlfn.XLOOKUP(K22,[2]目录表!$H:$H,[2]目录表!$AJ:$AJ) -> 散货
